Workbook

Sheet Base Consolidada
A1: Marca | B1: Responsável BDR | C1: Responsável Closer | D1: Status | E1: Status Completo | F1: Classificação | G1: Data do último FUP | H1: FCA - Qual próximo passo? | I1: 1. Iniciado | J1: 2. Primeiro Contato com a marca | K1: 3. Apresentação | L1: 4. Diagnóstico | M1: 5. Demo/Showroom | N1: 6. Negociação | O1: 7. Piloto | P1: 8. Contrato enviado | Q1: 9. Contrato assinado | R1: 10. Perdido | S1: 11. Stand by | T1: 12. Orgânico | U1: 13. Reativado | V1: Motivo da perda/stand by | W1: Mensalidade | X1: Tempo de contrato | Y1: Setup | Z1: Implantação | AA1: Qtd lojas físicas | AB1: Marca TOP KA | AC1: Marca no BP | AD1: PDV atual | AE1: Qtd de lojas | AF1: Mês de início | AG1: Qtd de meses | AH1: Qtd Lojas físicas qualificadas | AI1: Faturamento qualificado | AJ1: PDV/integradora atual | AK1: Tipo de serviço qualificado | AL1: Delivery abriu porta? | AM1: Base Elegível | AN1: Base Novos Produtos | AO1: Dias último FUP | AP1: Estado | AQ1: Coordenador Delivery | AR1: Executivo Delivery | AS1: Head Delivery | AT1: Gerente Delivery | AU1: Antigo Resp | AV1: Base Comer Fora | AW1: Prioridade Comer Fora | AX1: Ataque Comer Fora | AY1: PDV atual (2) | AZ1: Culinária | BA1: Ticket Médio | BB1: Perfil operacional | BC1: Localização Geográfica | BD1: Faturamento da rede | BE1: Lead Scoring | BF1: Percentual de Aderencia | BG1: Comparativo (Integradora atual x 3S) | BH1: Software Atual | BI1: Share Atual (%)
A2: =IFERROR(__xludf.DUMMYFUNCTION("IMPORTRANGE(""https://docs.google.com/spreadsheets/d/1fHelesWk1_KVNNgiTqliLjSdm_xdxzuv79w5l7MdQUk"",""CRM!B5:BA1707"")"),"A PIZZA DA MOOCA") -> A PIZZA DA MOOCA | B2: =IFERROR(__xludf.DUMMYFUNCTION("""COMPUTED_VALUE"""),"Lídia Esteves") -> Lídia Esteves | C2: =IFERROR(__xludf.DUMMYFUNCTION("""COMPUTED_VALUE"""),"Gabriela Roma") -> Gabriela Roma | D2: =IFERROR(__xludf.DUMMYFUNCTION("""COMPUTED_VALUE"""),"4. Diagnóstico") -> 4. Diagnóstico | E2: =IFERROR(__xludf.DUMMYFUNCTION("""COMPUTED_VALUE"""),"Pré-vendas - Em validação técnica") -> Pré-vendas - Em validação técnica | F2: =IFERROR(__xludf.DUMMYFUNCTION("""COMPUTED_VALUE"""),"P") -> P | G2: =IFERROR(__xludf.DUMMYFUNCTION("""COMPUTED_VALUE"""),46155.0) -> 46155 | H2: =IFERROR(__xludf.DUMMYFUNCTION("""COMPUTED_VALUE"""),"Agenda 12/05 presencial com a Rafa, parceiro tem interesse em colocar totem em 1 das lojas, sao 4 lojas no totem, só que 3 socios diferentes, o cliente que falamos ontem Derek é sócio da pizza onesta e pizza da mocca shop, usa aloha e quer mudar de pdv pr"&"a ter totem gratuito por ser do ifood, vamos enviar proposta mas nao sabemos se irá avanças por querer serviço gratuito do ifood, Samuca encontrará o socio de todas as lojas em chicago e vai conversar com ele") -> Agenda 12/05 presencial com a Rafa, parceiro tem interesse em colocar totem em 1 das lojas, sao 4 lojas no totem, só que 3 socios diferentes, o cliente que falamos ontem Derek é sócio da pizza onesta e pizza da mocca shop, usa aloha e quer mudar de pdv pra ter totem gratuito por ser do ifood, vamos enviar proposta mas nao sabemos se irá avanças por querer serviço gratuito do ifood, Samuca encontrará o socio de todas as lojas em chicago e vai conversar com ele | I2: =IFERROR(__xludf.DUMMYFUNCTION("""COMPUTED_VALUE"""),46118.67255412037) -> 46118.673 | J2: =IFERROR(__xludf.DUMMYFUNCTION("""COMPUTED_VALUE"""),46155.48445200232) -> 46155.484 | K2: =IFERROR(__xludf.DUMMYFUNCTION("""COMPUTED_VALUE"""),46155.484533877316) -> 46155.485 | L2: =IFERROR(__xludf.DUMMYFUNCTION("""COMPUTED_VALUE"""),46155.48459680556) -> 46155.485 | AA2: =IFERROR(__xludf.DUMMYFUNCTION("""COMPUTED_VALUE"""),4.0) -> 4 | AB2: =IFERROR(__xludf.DUMMYFUNCTION("""COMPUTED_VALUE"""),"CE") -> CE | AC2: =IFERROR(__xludf.DUMMYFUNCTION("""COMPUTED_VALUE"""),"Sim") -> Sim | AD2: =IFERROR(__xludf.DUMMYFUNCTION("""COMPUTED_VALUE"""),"Ifood") -> Ifood | AH2: =IFERROR(__xludf.DUMMYFUNCTION("""COMPUTED_VALUE"""),4.0) -> 4 | AI2: =IFERROR(__xludf.DUMMYFUNCTION("""COMPUTED_VALUE"""),0.0) -> 0 | AJ2: =IFERROR(__xludf.DUMMYFUNCTION("""COMPUTED_VALUE"""),"linx e aloha") -> linx e aloha | AK2: =IFERROR(__xludf.DUMMYFUNCTION("""COMPUTED_VALUE"""),"table sevice, quick service") -> table sevice, quick service | AL2: =IFERROR(__xludf.DUMMYFUNCTION("""COMPUTED_VALUE"""),"SIM") -> SIM | AM2: =IFERROR(__xludf.DUMMYFUNCTION("""COMPUTED_VALUE"""),"FY27") -> FY27 | AO2: =IFERROR(__xludf.DUMMYFUNCTION("""COMPUTED_VALUE"""),60.0) -> 60 | AP2: =IFERROR(__xludf.DUMMYFUNCTION("""COMPUTED_VALUE"""),"SP") -> SP | AQ2: =IFERROR(__xludf.DUMMYFUNCTION("""COMPUTED_VALUE"""),"GABRIEL CAMACHO") -> GABRIEL CAMACHO | AR2: =IFERROR(__xludf.DUMMYFUNCTION("""COMPUTED_VALUE"""),"KAIQUE RIBEIRO") -> KAIQUE RIBEIRO | AS2: =IFERROR(__xludf.DUMMYFUNCTION("""COMPUTED_VALUE"""),"NATHALIE MERTENS") -> NATHALIE MERTENS | AT2: =IFERROR(__xludf.DUMMYFUNCTION("""COMPUTED_VALUE"""),"MATHEUS LESSA") -> MATHEUS LESSA | AU2: =IFERROR(__xludf.DUMMYFUNCTION("""COMPUTED_VALUE"""),0.0) -> 0 | AV2: =IFERROR(__xludf.DUMMYFUNCTION("""COMPUTED_VALUE"""),0.0) -> 0 | AW2: =IFERROR(__xludf.DUMMYFUNCTION("""COMPUTED_VALUE"""),0.0) -> 0 | AX2: =IFERROR(__xludf.DUMMYFUNCTION("""COMPUTED_VALUE"""),0.0) -> 0 | AZ2: =IFERROR(__xludf.DUMMYFUNCTION("""COMPUTED_VALUE"""),"Brasileira") -> Brasileira | BA2: =IFERROR(__xludf.DUMMYFUNCTION("ARRAYFORMULA(IFERROR(VLOOKUP(A2:A1000,IMPORTRANGE(""https://docs.google.com/spreadsheets/d/15k1NdSDPraw4VxeDarc9u5amYqhWqDW8MjQ0Lzs-lQc"",""LOTE_1_ENRIQUECIDO.csv!A:I""),3,0),""""))"),95.0) -> 95 | BB2: =IFERROR(__xludf.DUMMYFUNCTION("ARRAYFORMULA(IFERROR(VLOOKUP(A2:A1000,IMPORTRANGE(""https://docs.google.com/spreadsheets/d/15k1NdSDPraw4VxeDarc9u5amYqhWqDW8MjQ0Lzs-lQc"",""LOTE_1_ENRIQUECIDO.csv!A:I""),4,0),""""))"),"Fast Casual - Pizza Napoletana") -> Fast Casual - Pizza Napoletana | BC2: =IFERROR(__xludf.DUMMYFUNCTION("ARRAYFORMULA(IFERROR(VLOOKUP(A2:A1000,IMPORTRANGE(""https://docs.google.com/spreadsheets/d/15k1NdSDPraw4VxeDarc9u5amYqhWqDW8MjQ0Lzs-lQc"",""LOTE_1_ENRIQUECIDO.csv!A:I""),5,0),""""))"),"São Paulo/SP (3 unidades)") -> São Paulo/SP (3 unidades) | BD2: =IFERROR(__xludf.DUMMYFUNCTION("ARRAYFORMULA(IFERROR(VLOOKUP(A2:A1000,IMPORTRANGE(""https://docs.google.com/spreadsheets/d/15k1NdSDPraw4VxeDarc9u5amYqhWqDW8MjQ0Lzs-lQc"",""LOTE_1_ENRIQUECIDO.csv!A:I""),6,0),""""))"),"") | BE2: =IFERROR(__xludf.DUMMYFUNCTION("ARRAYFORMULA(IFERROR(VLOOKUP(A2:A1000,IMPORTRANGE(""https://docs.google.com/spreadsheets/d/15k1NdSDPraw4VxeDarc9u5amYqhWqDW8MjQ0Lzs-lQc"",""LOTE_1_ENRIQUECIDO.csv!A:I""),7,0),""""))"),65.0) -> 65 | BF2: =IFERROR(__xludf.DUMMYFUNCTION("ARRAYFORMULA(IFERROR(VLOOKUP(A2:A1000,IMPORTRANGE(""https://docs.google.com/spreadsheets/d/15k1NdSDPraw4VxeDarc9u5amYqhWqDW8MjQ0Lzs-lQc"",""LOTE_1_ENRIQUECIDO.csv!A:I""),8,0),""""))"),0.75) -> 0.75 | BG2: =IFERROR(__xludf.DUMMYFUNCTION("ARRAYFORMULA(IFERROR(VLOOKUP(A2:A1000,IMPORTRANGE(""https://docs.google.com/spreadsheets/d/15k1NdSDPraw4VxeDarc9u5amYqhWqDW8MjQ0Lzs-lQc"",""LOTE_1_ENRIQUECIDO.csv!A:I""),9,0),""""))"),"Aderência forte ao 3S: PDV atual não identificado. 3S oferece PDV robusto, KDS integrado e mobilidade (3SGO) para gestão em tempo real - ideal para operações multi-canal.") -> Aderência forte ao 3S: PDV atual não identificado. 3S oferece PDV robusto, KDS integrado e mobilidade (3SGO) para gestão em tempo real - ideal para operações multi-canal. | BH2: {=IFERROR(VLOOKUP(A2:A1000,'_Fonte_A2'!K:X,13,0),"")} -> Stone Co. | BI2: {=IFERROR(VLOOKUP(A2:A1000,'_Fonte_A2'!K:X,14,0),"")} -> 0.44444444
A3: =IFERROR(__xludf.DUMMYFUNCTION("""COMPUTED_VALUE"""),"ACAI BEAT") -> ACAI BEAT | B3: =IFERROR(__xludf.DUMMYFUNCTION("""COMPUTED_VALUE"""),"Lídia Esteves") -> Lídia Esteves | C3: =IFERROR(__xludf.DUMMYFUNCTION("""COMPUTED_VALUE"""),"Gabriela Roma") -> Gabriela Roma | D3: =IFERROR(__xludf.DUMMYFUNCTION("""COMPUTED_VALUE"""),"0. Não Iniciado") -> 0. Não Iniciado | F3: =IFERROR(__xludf.DUMMYFUNCTION("""COMPUTED_VALUE"""),"M") -> M | AA3: =IFERROR(__xludf.DUMMYFUNCTION("""COMPUTED_VALUE"""),30.0) -> 30 | AB3: =IFERROR(__xludf.DUMMYFUNCTION("""COMPUTED_VALUE"""),"-") -> - | AC3: =IFERROR(__xludf.DUMMYFUNCTION("""COMPUTED_VALUE"""),"Sim") -> Sim | AD3: =IFERROR(__xludf.DUMMYFUNCTION("""COMPUTED_VALUE"""),0.0) -> 0 | AM3: =IFERROR(__xludf.DUMMYFUNCTION("""COMPUTED_VALUE"""),"FY27") -> FY27 | AO3: =IFERROR(__xludf.DUMMYFUNCTION("""COMPUTED_VALUE"""),45553.0) -> 45553 | AP3: =IFERROR(__xludf.DUMMYFUNCTION("""COMPUTED_VALUE"""),"RJ") -> RJ | AQ3: =IFERROR(__xludf.DUMMYFUNCTION("""COMPUTED_VALUE"""),"EMILLY BIASI") -> EMILLY BIASI | AR3: =IFERROR(__xludf.DUMMYFUNCTION("""COMPUTED_VALUE"""),0.0) -> 0 | AS3: =IFERROR(__xludf.DUMMYFUNCTION("""COMPUTED_VALUE"""),"ALAN HADDAD") -> ALAN HADDAD | AT3: =IFERROR(__xludf.DUMMYFUNCTION("""COMPUTED_VALUE"""),"ISABELA DINIZ") -> ISABELA DINIZ | AU3: =IFERROR(__xludf.DUMMYFUNCTION("""COMPUTED_VALUE"""),0.0) -> 0 | AV3: =IFERROR(__xludf.DUMMYFUNCTION("""COMPUTED_VALUE"""),0.0) -> 0 | AW3: =IFERROR(__xludf.DUMMYFUNCTION("""COMPUTED_VALUE"""),0.0) -> 0 | AX3: =IFERROR(__xludf.DUMMYFUNCTION("""COMPUTED_VALUE"""),0.0) -> 0 | AY3: =IFERROR(__xludf.DUMMYFUNCTION("""COMPUTED_VALUE"""),"Cardápio Web") -> Cardápio Web | AZ3: =IFERROR(__xludf.DUMMYFUNCTION("""COMPUTED_VALUE"""),"Saudável") -> Saudável | BA3: =IFERROR(__xludf.DUMMYFUNCTION("""COMPUTED_VALUE"""),30.0) -> 30 | BB3: =IFERROR(__xludf.DUMMYFUNCTION("""COMPUTED_VALUE"""),"QSR - Açaí Bowl") -> QSR - Açaí Bowl | BC3: =IFERROR(__xludf.DUMMYFUNCTION("""COMPUTED_VALUE"""),"MT, SP (interior), MG, RJ") -> MT, SP (interior), MG, RJ | BE3: =IFERROR(__xludf.DUMMYFUNCTION("""COMPUTED_VALUE"""),75.0) -> 75 | BF3: =IFERROR(__xludf.DUMMYFUNCTION("""COMPUTED_VALUE"""),0.9) -> 0.9 | BG3: =IFERROR(__xludf.DUMMYFUNCTION("""COMPUTED_VALUE"""),"Alta aderência ao 3S: PDV atual não identificado. 3S oferece Kiosk nativo, Hub Delivery integrado e gestão centralizada multi-loja - diferenciais competitivos para expansão e redução de filas.") -> Alta aderência ao 3S: PDV atual não identificado. 3S oferece Kiosk nativo, Hub Delivery integrado e gestão centralizada multi-loja - diferenciais competitivos para expansão e redução de filas. | BH3: Cardápio Web | BI3: 0.66666667
A4: =IFERROR(__xludf.DUMMYFUNCTION("""COMPUTED_VALUE"""),"ACAI DA CIDADE") -> ACAI DA CIDADE | B4: =IFERROR(__xludf.DUMMYFUNCTION("""COMPUTED_VALUE"""),"João Biagiotti") -> João Biagiotti | C4: =IFERROR(__xludf.DUMMYFUNCTION("""COMPUTED_VALUE"""),"Diego Santos") -> Diego Santos | D4: =IFERROR(__xludf.DUMMYFUNCTION("""COMPUTED_VALUE"""),"0. Não Iniciado") -> 0. Não Iniciado | F4: =IFERROR(__xludf.DUMMYFUNCTION("""COMPUTED_VALUE"""),"P") -> P | AA4: =IFERROR(__xludf.DUMMYFUNCTION("""COMPUTED_VALUE"""),14.0) -> 14 | AB4: =IFERROR(__xludf.DUMMYFUNCTION("""COMPUTED_VALUE"""),"CE") -> CE | AC4: =IFERROR(__xludf.DUMMYFUNCTION("""COMPUTED_VALUE"""),"Sim") -> Sim | AD4: =IFERROR(__xludf.DUMMYFUNCTION("""COMPUTED_VALUE"""),0.0) -> 0 | AM4: =IFERROR(__xludf.DUMMYFUNCTION("""COMPUTED_VALUE"""),"FY27") -> FY27 | AO4: =IFERROR(__xludf.DUMMYFUNCTION("""COMPUTED_VALUE"""),45553.0) -> 45553 | AP4: =IFERROR(__xludf.DUMMYFUNCTION("""COMPUTED_VALUE"""),"SP") -> SP | AQ4: =IFERROR(__xludf.DUMMYFUNCTION("""COMPUTED_VALUE"""),"CARLOS ALBRECHT") -> CARLOS ALBRECHT | AR4: =IFERROR(__xludf.DUMMYFUNCTION("""COMPUTED_VALUE"""),0.0) -> 0 | AS4: =IFERROR(__xludf.DUMMYFUNCTION("""COMPUTED_VALUE"""),"FABIO DONATO") -> FABIO DONATO | AT4: =IFERROR(__xludf.DUMMYFUNCTION("""COMPUTED_VALUE"""),"GILSON JUNIOR") -> GILSON JUNIOR | AU4: =IFERROR(__xludf.DUMMYFUNCTION("""COMPUTED_VALUE"""),0.0) -> 0 | AV4: =IFERROR(__xludf.DUMMYFUNCTION("""COMPUTED_VALUE"""),0.0) -> 0 | AW4: =IFERROR(__xludf.DUMMYFUNCTION("""COMPUTED_VALUE"""),0.0) -> 0 | AX4: =IFERROR(__xludf.DUMMYFUNCTION("""COMPUTED_VALUE"""),0.0) -> 0 | AZ4: =IFERROR(__xludf.DUMMYFUNCTION("""COMPUTED_VALUE"""),"Açaí") -> Açaí | BA4: =IFERROR(__xludf.DUMMYFUNCTION("""COMPUTED_VALUE"""),25.0) -> 25 | BB4: =IFERROR(__xludf.DUMMYFUNCTION("""COMPUTED_VALUE"""),"QSR - Açaí") -> QSR - Açaí | BC4: =IFERROR(__xludf.DUMMYFUNCTION("""COMPUTED_VALUE"""),"Interior SP (Jundiaí, Campinas, Piracicaba)") -> Interior SP (Jundiaí, Campinas, Piracicaba) | BE4: =IFERROR(__xludf.DUMMYFUNCTION("""COMPUTED_VALUE"""),70.0) -> 70 | BF4: =IFERROR(__xludf.DUMMYFUNCTION("""COMPUTED_VALUE"""),0.9) -> 0.9 | BG4: =IFERROR(__xludf.DUMMYFUNCTION("""COMPUTED_VALUE"""),"Alta aderência ao 3S: PDV atual não identificado. 3S oferece Kiosk nativo, Hub Delivery integrado e gestão centralizada multi-loja - diferenciais competitivos para expansão e redução de filas.") -> Alta aderência ao 3S: PDV atual não identificado. 3S oferece Kiosk nativo, Hub Delivery integrado e gestão centralizada multi-loja - diferenciais competitivos para expansão e redução de filas. | BH4: Get Soft Software House Tecnologia Da Informacao Ltda | BI4: 0.85714286
A5: =IFERROR(__xludf.DUMMYFUNCTION("""COMPUTED_VALUE"""),"ACAI DA HORA - CONTA MARCA") -> ACAI DA HORA - CONTA MARCA | B5: =IFERROR(__xludf.DUMMYFUNCTION("""COMPUTED_VALUE"""),"João Biagiotti") -> João Biagiotti | C5: =IFERROR(__xludf.DUMMYFUNCTION("""COMPUTED_VALUE"""),"Diego Santos") -> Diego Santos | D5: =IFERROR(__xludf.DUMMYFUNCTION("""COMPUTED_VALUE"""),"9. Contrato assinado") -> 9. Contrato assinado | F5: =IFERROR(__xludf.DUMMYFUNCTION("""COMPUTED_VALUE"""),"P") -> P | O5: =IFERROR(__xludf.DUMMYFUNCTION("""COMPUTED_VALUE"""),46128.44601299769) -> 46128.446 | W5: =IFERROR(__xludf.DUMMYFUNCTION("""COMPUTED_VALUE"""),500.0) -> 500 | X5: =IFERROR(__xludf.DUMMYFUNCTION("""COMPUTED_VALUE"""),24.0) -> 24 | Y5: =IFERROR(__xludf.DUMMYFUNCTION("""COMPUTED_VALUE"""),1200.0) -> 1200 | Z5: =IFERROR(__xludf.DUMMYFUNCTION("""COMPUTED_VALUE"""),3000.0) -> 3000 | AA5: =IFERROR(__xludf.DUMMYFUNCTION("""COMPUTED_VALUE"""),14.0) -> 14 | AB5: =IFERROR(__xludf.DUMMYFUNCTION("""COMPUTED_VALUE"""),"CE") -> CE | AC5: =IFERROR(__xludf.DUMMYFUNCTION("""COMPUTED_VALUE"""),"Sim") -> Sim | AD5: =IFERROR(__xludf.DUMMYFUNCTION("""COMPUTED_VALUE"""),"Ifood") -> Ifood | AE5: =IFERROR(__xludf.DUMMYFUNCTION("""COMPUTED_VALUE"""),2.0) -> 2 | AF5: =IFERROR(__xludf.DUMMYFUNCTION("""COMPUTED_VALUE"""),46113.0) -> 46113 | AG5: =IFERROR(__xludf.DUMMYFUNCTION("""COMPUTED_VALUE"""),"2 meses") -> 2 meses | AM5: =IFERROR(__xludf.DUMMYFUNCTION("""COMPUTED_VALUE"""),"FY27") -> FY27 | AO5: =IFERROR(__xludf.DUMMYFUNCTION("""COMPUTED_VALUE"""),45553.0) -> 45553 | AP5: =IFERROR(__xludf.DUMMYFUNCTION("""COMPUTED_VALUE"""),"MG") -> MG | AQ5: =IFERROR(__xludf.DUMMYFUNCTION("""COMPUTED_VALUE"""),"TAMIRES DIAS") -> TAMIRES DIAS | AR5: =IFERROR(__xludf.DUMMYFUNCTION("""COMPUTED_VALUE"""),"MARIANA ACRUX") -> MARIANA ACRUX | AS5: =IFERROR(__xludf.DUMMYFUNCTION("""COMPUTED_VALUE"""),"#REF!") -> #REF! | AT5: =IFERROR(__xludf.DUMMYFUNCTION("""COMPUTED_VALUE"""),"#REF!") -> #REF! | AU5: =IFERROR(__xludf.DUMMYFUNCTION("""COMPUTED_VALUE"""),"#REF!") -> #REF! | AV5: =IFERROR(__xludf.DUMMYFUNCTION("""COMPUTED_VALUE"""),"#REF!") -> #REF! | AW5: =IFERROR(__xludf.DUMMYFUNCTION("""COMPUTED_VALUE"""),"#REF!") -> #REF! | AX5: =IFERROR(__xludf.DUMMYFUNCTION("""COMPUTED_VALUE"""),"#REF!") -> #REF! | AZ5: =IFERROR(__xludf.DUMMYFUNCTION("""COMPUTED_VALUE"""),"Açaí") -> Açaí | BA5: =IFERROR(__xludf.DUMMYFUNCTION("""COMPUTED_VALUE"""),"") | BB5: =IFERROR(__xludf.DUMMYFUNCTION("""COMPUTED_VALUE"""),"") | BC5: =IFERROR(__xludf.DUMMYFUNCTION("""COMPUTED_VALUE"""),"") | BD5: =IFERROR(__xludf.DUMMYFUNCTION("""COMPUTED_VALUE"""),"") | BE5: =IFERROR(__xludf.DUMMYFUNCTION("""COMPUTED_VALUE"""),"") | BF5: =IFERROR(__xludf.DUMMYFUNCTION("""COMPUTED_VALUE"""),"") | BG5: =IFERROR(__xludf.DUMMYFUNCTION("""COMPUTED_VALUE"""),"")
A6: =IFERROR(__xludf.DUMMYFUNCTION("""COMPUTED_VALUE"""),"ACAI DO FORTE - CONTA PAI") -> ACAI DO FORTE - CONTA PAI | B6: =IFERROR(__xludf.DUMMYFUNCTION("""COMPUTED_VALUE"""),"Lídia Esteves") -> Lídia Esteves | C6: =IFERROR(__xludf.DUMMYFUNCTION("""COMPUTED_VALUE"""),"Gabriela Roma") -> Gabriela Roma | D6: =IFERROR(__xludf.DUMMYFUNCTION("""COMPUTED_VALUE"""),"0. Não Iniciado") -> 0. Não Iniciado | F6: =IFERROR(__xludf.DUMMYFUNCTION("""COMPUTED_VALUE"""),"P") -> P | AA6: =IFERROR(__xludf.DUMMYFUNCTION("""COMPUTED_VALUE"""),14.0) -> 14 | AB6: =IFERROR(__xludf.DUMMYFUNCTION("""COMPUTED_VALUE"""),"CE") -> CE | AC6: =IFERROR(__xludf.DUMMYFUNCTION("""COMPUTED_VALUE"""),"Sim") -> Sim | AD6: =IFERROR(__xludf.DUMMYFUNCTION("""COMPUTED_VALUE"""),"Ifood") -> Ifood | AM6: =IFERROR(__xludf.DUMMYFUNCTION("""COMPUTED_VALUE"""),"FY27") -> FY27 | AO6: =IFERROR(__xludf.DUMMYFUNCTION("""COMPUTED_VALUE"""),45553.0) -> 45553 | AP6: =IFERROR(__xludf.DUMMYFUNCTION("""COMPUTED_VALUE"""),"RJ") -> RJ | AQ6: =IFERROR(__xludf.DUMMYFUNCTION("""COMPUTED_VALUE"""),"JUAN CHAROTTA") -> JUAN CHAROTTA | AR6: =IFERROR(__xludf.DUMMYFUNCTION("""COMPUTED_VALUE"""),"MARCELLA GUIMARAES") -> MARCELLA GUIMARAES | AS6: =IFERROR(__xludf.DUMMYFUNCTION("""COMPUTED_VALUE"""),"NATHALIE MERTENS") -> NATHALIE MERTENS | AT6: =IFERROR(__xludf.DUMMYFUNCTION("""COMPUTED_VALUE"""),"NATALIA COUTINHO") -> NATALIA COUTINHO | AU6: =IFERROR(__xludf.DUMMYFUNCTION("""COMPUTED_VALUE"""),0.0) -> 0 | AV6: =IFERROR(__xludf.DUMMYFUNCTION("""COMPUTED_VALUE"""),0.0) -> 0 | AW6: =IFERROR(__xludf.DUMMYFUNCTION("""COMPUTED_VALUE"""),0.0) -> 0 | AX6: =IFERROR(__xludf.DUMMYFUNCTION("""COMPUTED_VALUE"""),0.0) -> 0 | AZ6: =IFERROR(__xludf.DUMMYFUNCTION("""COMPUTED_VALUE"""),"Açaí") -> Açaí | BA6: =IFERROR(__xludf.DUMMYFUNCTION("""COMPUTED_VALUE"""),"") | BB6: =IFERROR(__xludf.DUMMYFUNCTION("""COMPUTED_VALUE"""),"") | BC6: =IFERROR(__xludf.DUMMYFUNCTION("""COMPUTED_VALUE"""),"") | BD6: =IFERROR(__xludf.DUMMYFUNCTION("""COMPUTED_VALUE"""),"") | BE6: =IFERROR(__xludf.DUMMYFUNCTION("""COMPUTED_VALUE"""),"") | BF6: =IFERROR(__xludf.DUMMYFUNCTION("""COMPUTED_VALUE"""),"") | BG6: =IFERROR(__xludf.DUMMYFUNCTION("""COMPUTED_VALUE"""),"")
A7: =IFERROR(__xludf.DUMMYFUNCTION("""COMPUTED_VALUE"""),"ACAI LAFRESCO") -> ACAI LAFRESCO | B7: =IFERROR(__xludf.DUMMYFUNCTION("""COMPUTED_VALUE"""),"João Biagiotti") -> João Biagiotti | C7: =IFERROR(__xludf.DUMMYFUNCTION("""COMPUTED_VALUE"""),"Diego Santos") -> Diego Santos | D7: =IFERROR(__xludf.DUMMYFUNCTION("""COMPUTED_VALUE"""),"0. Não Iniciado") -> 0. Não Iniciado | F7: =IFERROR(__xludf.DUMMYFUNCTION("""COMPUTED_VALUE"""),"P") -> P | AA7: =IFERROR(__xludf.DUMMYFUNCTION("""COMPUTED_VALUE"""),5.0) -> 5 | AB7: =IFERROR(__xludf.DUMMYFUNCTION("""COMPUTED_VALUE"""),"CE") -> CE | AC7: =IFERROR(__xludf.DUMMYFUNCTION("""COMPUTED_VALUE"""),"Sim") -> Sim | AD7: =IFERROR(__xludf.DUMMYFUNCTION("""COMPUTED_VALUE"""),"Ifood") -> Ifood | AM7: =IFERROR(__xludf.DUMMYFUNCTION("""COMPUTED_VALUE"""),"FY27") -> FY27 | AO7: =IFERROR(__xludf.DUMMYFUNCTION("""COMPUTED_VALUE"""),45553.0) -> 45553 | AP7: =IFERROR(__xludf.DUMMYFUNCTION("""COMPUTED_VALUE"""),"SP") -> SP | AQ7: =IFERROR(__xludf.DUMMYFUNCTION("""COMPUTED_VALUE"""),"CARLOS ALBRECHT") -> CARLOS ALBRECHT | AR7: =IFERROR(__xludf.DUMMYFUNCTION("""COMPUTED_VALUE"""),"GUILHERME VIEIRA") -> GUILHERME VIEIRA | AS7: =IFERROR(__xludf.DUMMYFUNCTION("""COMPUTED_VALUE"""),"ALAN HADDAD") -> ALAN HADDAD | AT7: =IFERROR(__xludf.DUMMYFUNCTION("""COMPUTED_VALUE"""),"ISABELA DINIZ") -> ISABELA DINIZ | AU7: =IFERROR(__xludf.DUMMYFUNCTION("""COMPUTED_VALUE"""),0.0) -> 0 | AV7: =IFERROR(__xludf.DUMMYFUNCTION("""COMPUTED_VALUE"""),0.0) -> 0 | AW7: =IFERROR(__xludf.DUMMYFUNCTION("""COMPUTED_VALUE"""),0.0) -> 0 | AX7: =IFERROR(__xludf.DUMMYFUNCTION("""COMPUTED_VALUE"""),0.0) -> 0 | AZ7: =IFERROR(__xludf.DUMMYFUNCTION("""COMPUTED_VALUE"""),"Saudável") -> Saudável | BA7: =IFERROR(__xludf.DUMMYFUNCTION("""COMPUTED_VALUE"""),"") | BB7: =IFERROR(__xludf.DUMMYFUNCTION("""COMPUTED_VALUE"""),"") | BC7: =IFERROR(__xludf.DUMMYFUNCTION("""COMPUTED_VALUE"""),"") | BD7: =IFERROR(__xludf.DUMMYFUNCTION("""COMPUTED_VALUE"""),"") | BE7: =IFERROR(__xludf.DUMMYFUNCTION("""COMPUTED_VALUE"""),"") | BF7: =IFERROR(__xludf.DUMMYFUNCTION("""COMPUTED_VALUE"""),"") | BG7: =IFERROR(__xludf.DUMMYFUNCTION("""COMPUTED_VALUE"""),"")
A8: =IFERROR(__xludf.DUMMYFUNCTION("""COMPUTED_VALUE"""),"ADEGA DO BOI TERESINA") -> ADEGA DO BOI TERESINA | B8: =IFERROR(__xludf.DUMMYFUNCTION("""COMPUTED_VALUE"""),"João Biagiotti") -> João Biagiotti | C8: =IFERROR(__xludf.DUMMYFUNCTION("""COMPUTED_VALUE"""),"Diego Santos") -> Diego Santos | D8: =IFERROR(__xludf.DUMMYFUNCTION("""COMPUTED_VALUE"""),"0. Não Iniciado") -> 0. Não Iniciado | F8: =IFERROR(__xludf.DUMMYFUNCTION("""COMPUTED_VALUE"""),"P") -> P | AA8: =IFERROR(__xludf.DUMMYFUNCTION("""COMPUTED_VALUE"""),5.0) -> 5 | AB8: =IFERROR(__xludf.DUMMYFUNCTION("""COMPUTED_VALUE"""),"CE") -> CE | AC8: =IFERROR(__xludf.DUMMYFUNCTION("""COMPUTED_VALUE"""),"Sim") -> Sim | AD8: =IFERROR(__xludf.DUMMYFUNCTION("""COMPUTED_VALUE"""),"Ifood") -> Ifood | AM8: =IFERROR(__xludf.DUMMYFUNCTION("""COMPUTED_VALUE"""),"FY27") -> FY27 | AO8: =IFERROR(__xludf.DUMMYFUNCTION("""COMPUTED_VALUE"""),45553.0) -> 45553 | AP8: =IFERROR(__xludf.DUMMYFUNCTION("""COMPUTED_VALUE"""),"PI") -> PI | AQ8: =IFERROR(__xludf.DUMMYFUNCTION("""COMPUTED_VALUE"""),"GEORGE STEIN") -> GEORGE STEIN | AR8: =IFERROR(__xludf.DUMMYFUNCTION("""COMPUTED_VALUE"""),"RAULLI SOARES") -> RAULLI SOARES | AS8: =IFERROR(__xludf.DUMMYFUNCTION("""COMPUTED_VALUE"""),"THIAGO ROMAGNOLE") -> THIAGO ROMAGNOLE | AT8: =IFERROR(__xludf.DUMMYFUNCTION("""COMPUTED_VALUE"""),"EDUARDO VAZ") -> EDUARDO VAZ | AU8: =IFERROR(__xludf.DUMMYFUNCTION("""COMPUTED_VALUE"""),0.0) -> 0 | AV8: =IFERROR(__xludf.DUMMYFUNCTION("""COMPUTED_VALUE"""),0.0) -> 0 | AW8: =IFERROR(__xludf.DUMMYFUNCTION("""COMPUTED_VALUE"""),0.0) -> 0 | AX8: =IFERROR(__xludf.DUMMYFUNCTION("""COMPUTED_VALUE"""),0.0) -> 0 | AZ8: =IFERROR(__xludf.DUMMYFUNCTION("""COMPUTED_VALUE"""),"Doces & Bolos") -> Doces & Bolos | BA8: =IFERROR(__xludf.DUMMYFUNCTION("""COMPUTED_VALUE"""),120.0) -> 120 | BB8: =IFERROR(__xludf.DUMMYFUNCTION("""COMPUTED_VALUE"""),"Table Service - Churrascaria") -> Table Service - Churrascaria | BC8: =IFERROR(__xludf.DUMMYFUNCTION("""COMPUTED_VALUE"""),"Teresina/PI") -> Teresina/PI | BE8: =IFERROR(__xludf.DUMMYFUNCTION("""COMPUTED_VALUE"""),55.0) -> 55 | BF8: =IFERROR(__xludf.DUMMYFUNCTION("""COMPUTED_VALUE"""),0.65) -> 0.65 | BG8: =IFERROR(__xludf.DUMMYFUNCTION("""COMPUTED_VALUE"""),"Aderência forte ao 3S: PDV atual não identificado. 3S oferece PDV robusto, KDS integrado e mobilidade (3SGO) para gestão em tempo real - ideal para operações multi-canal.") -> Aderência forte ao 3S: PDV atual não identificado. 3S oferece PDV robusto, KDS integrado e mobilidade (3SGO) para gestão em tempo real - ideal para operações multi-canal.
A9: =IFERROR(__xludf.DUMMYFUNCTION("""COMPUTED_VALUE"""),"AKIRO SUSHI") -> AKIRO SUSHI | B9: =IFERROR(__xludf.DUMMYFUNCTION("""COMPUTED_VALUE"""),"Lídia Esteves") -> Lídia Esteves | C9: =IFERROR(__xludf.DUMMYFUNCTION("""COMPUTED_VALUE"""),"Gabriela Roma") -> Gabriela Roma | D9: =IFERROR(__xludf.DUMMYFUNCTION("""COMPUTED_VALUE"""),"5. Demo/Showroom") -> 5. Demo/Showroom | E9: =IFERROR(__xludf.DUMMYFUNCTION("""COMPUTED_VALUE"""),"Pré-vendas - Demonstração / Showroom") -> Pré-vendas - Demonstração / Showroom | F9: =IFERROR(__xludf.DUMMYFUNCTION("""COMPUTED_VALUE"""),"P") -> P | G9: =IFERROR(__xludf.DUMMYFUNCTION("""COMPUTED_VALUE"""),46154.0) -> 46154 | H9: =IFERROR(__xludf.DUMMYFUNCTION("""COMPUTED_VALUE"""),"demo agendada para 14/5") -> demo agendada para 14/5 | I9: =IFERROR(__xludf.DUMMYFUNCTION("""COMPUTED_VALUE"""),46122.67191171296) -> 46122.672 | J9: =IFERROR(__xludf.DUMMYFUNCTION("""COMPUTED_VALUE"""),46139.72232130787) -> 46139.722 | K9: =IFERROR(__xludf.DUMMYFUNCTION("""COMPUTED_VALUE"""),46140.40413303241) -> 46140.404 | L9: =IFERROR(__xludf.DUMMYFUNCTION("""COMPUTED_VALUE"""),46153.67861347222) -> 46153.679 | M9: =IFERROR(__xludf.DUMMYFUNCTION("""COMPUTED_VALUE"""),46153.681405243056) -> 46153.681 | AA9: =IFERROR(__xludf.DUMMYFUNCTION("""COMPUTED_VALUE"""),5.0) -> 5 | AB9: =IFERROR(__xludf.DUMMYFUNCTION("""COMPUTED_VALUE"""),"CE") -> CE | AC9: =IFERROR(__xludf.DUMMYFUNCTION("""COMPUTED_VALUE"""),"Sim") -> Sim | AD9: =IFERROR(__xludf.DUMMYFUNCTION("""COMPUTED_VALUE"""),"Ifood") -> Ifood | AH9: =IFERROR(__xludf.DUMMYFUNCTION("""COMPUTED_VALUE"""),4.0) -> 4 | AI9: =IFERROR(__xludf.DUMMYFUNCTION("""COMPUTED_VALUE"""),300000.0) -> 300000 | AJ9: =IFERROR(__xludf.DUMMYFUNCTION("""COMPUTED_VALUE"""),"sistema local") -> sistema local | AK9: =IFERROR(__xludf.DUMMYFUNCTION("""COMPUTED_VALUE"""),"salão e delivery") -> salão e delivery | AL9: =IFERROR(__xludf.DUMMYFUNCTION("""COMPUTED_VALUE"""),"SIM") -> SIM | AM9: =IFERROR(__xludf.DUMMYFUNCTION("""COMPUTED_VALUE"""),"FY27") -> FY27 | AO9: =IFERROR(__xludf.DUMMYFUNCTION("""COMPUTED_VALUE"""),61.0) -> 61 | AP9: =IFERROR(__xludf.DUMMYFUNCTION("""COMPUTED_VALUE"""),"RJ") -> RJ | AQ9: =IFERROR(__xludf.DUMMYFUNCTION("""COMPUTED_VALUE"""),"JUAN CHAROTTA") -> JUAN CHAROTTA | AR9: =IFERROR(__xludf.DUMMYFUNCTION("""COMPUTED_VALUE"""),"BRUNA MEDEIROS") -> BRUNA MEDEIROS | AS9: =IFERROR(__xludf.DUMMYFUNCTION("""COMPUTED_VALUE"""),"NATHALIE MERTENS") -> NATHALIE MERTENS | AT9: =IFERROR(__xludf.DUMMYFUNCTION("""COMPUTED_VALUE"""),"NATALIA COUTINHO") -> NATALIA COUTINHO | AU9: =IFERROR(__xludf.DUMMYFUNCTION("""COMPUTED_VALUE"""),0.0) -> 0 | AV9: =IFERROR(__xludf.DUMMYFUNCTION("""COMPUTED_VALUE"""),0.0) -> 0 | AW9: =IFERROR(__xludf.DUMMYFUNCTION("""COMPUTED_VALUE"""),0.0) -> 0 | AX9: =IFERROR(__xludf.DUMMYFUNCTION("""COMPUTED_VALUE"""),0.0) -> 0 | AZ9: =IFERROR(__xludf.DUMMYFUNCTION("""COMPUTED_VALUE"""),"Japonesa") -> Japonesa | BA9: =IFERROR(__xludf.DUMMYFUNCTION("""COMPUTED_VALUE"""),95.0) -> 95 | BB9: =IFERROR(__xludf.DUMMYFUNCTION("""COMPUTED_VALUE"""),"Table Service/Delivery - Rodízio Japonês") -> Table Service/Delivery - Rodízio Japonês | BC9: =IFERROR(__xludf.DUMMYFUNCTION("""COMPUTED_VALUE"""),"Grande Rio/RJ") -> Grande Rio/RJ | BE9: =IFERROR(__xludf.DUMMYFUNCTION("""COMPUTED_VALUE"""),60.0) -> 60 | BF9: =IFERROR(__xludf.DUMMYFUNCTION("""COMPUTED_VALUE"""),0.65) -> 0.65 | BG9: =IFERROR(__xludf.DUMMYFUNCTION("""COMPUTED_VALUE"""),"Aderência forte ao 3S: PDV atual não identificado. 3S oferece PDV robusto, KDS integrado e mobilidade (3SGO) para gestão em tempo real - ideal para operações multi-canal.") -> Aderência forte ao 3S: PDV atual não identificado. 3S oferece PDV robusto, KDS integrado e mobilidade (3SGO) para gestão em tempo real - ideal para operações multi-canal.
A10: =IFERROR(__xludf.DUMMYFUNCTION("""COMPUTED_VALUE"""),"BIG PIZZA") -> BIG PIZZA | B10: =IFERROR(__xludf.DUMMYFUNCTION("""COMPUTED_VALUE"""),"João Biagiotti") -> João Biagiotti | C10: =IFERROR(__xludf.DUMMYFUNCTION("""COMPUTED_VALUE"""),"Diego Santos") -> Diego Santos | D10: =IFERROR(__xludf.DUMMYFUNCTION("""COMPUTED_VALUE"""),"0. Não Iniciado") -> 0. Não Iniciado | F10: =IFERROR(__xludf.DUMMYFUNCTION("""COMPUTED_VALUE"""),"P") -> P | AA10: =IFERROR(__xludf.DUMMYFUNCTION("""COMPUTED_VALUE"""),11.0) -> 11 | AB10: =IFERROR(__xludf.DUMMYFUNCTION("""COMPUTED_VALUE"""),"Não Encarteirado") -> Não Encarteirado | AC10: =IFERROR(__xludf.DUMMYFUNCTION("""COMPUTED_VALUE"""),"Sim") -> Sim | AD10: =IFERROR(__xludf.DUMMYFUNCTION("""COMPUTED_VALUE"""),0.0) -> 0 | AM10: =IFERROR(__xludf.DUMMYFUNCTION("""COMPUTED_VALUE"""),"FY27") -> FY27 | AO10: =IFERROR(__xludf.DUMMYFUNCTION("""COMPUTED_VALUE"""),45553.0) -> 45553 | AP10: =IFERROR(__xludf.DUMMYFUNCTION("""COMPUTED_VALUE"""),"SP") -> SP | AQ10: =IFERROR(__xludf.DUMMYFUNCTION("""COMPUTED_VALUE"""),"LAURA APOLINARIO") -> LAURA APOLINARIO | AR10: =IFERROR(__xludf.DUMMYFUNCTION("""COMPUTED_VALUE"""),0.0) -> 0 | AS10: =IFERROR(__xludf.DUMMYFUNCTION("""COMPUTED_VALUE"""),0.0) -> 0 | AT10: =IFERROR(__xludf.DUMMYFUNCTION("""COMPUTED_VALUE"""),0.0) -> 0 | AU10: =IFERROR(__xludf.DUMMYFUNCTION("""COMPUTED_VALUE"""),0.0) -> 0 | AV10: =IFERROR(__xludf.DUMMYFUNCTION("""COMPUTED_VALUE"""),0.0) -> 0 | AW10: =IFERROR(__xludf.DUMMYFUNCTION("""COMPUTED_VALUE"""),0.0) -> 0 | AX10: =IFERROR(__xludf.DUMMYFUNCTION("""COMPUTED_VALUE"""),0.0) -> 0 | AY10: =IFERROR(__xludf.DUMMYFUNCTION("""COMPUTED_VALUE"""),"Anota Ai Solucoes Digitais S/a") -> Anota Ai Solucoes Digitais S/a | AZ10: =IFERROR(__xludf.DUMMYFUNCTION("""COMPUTED_VALUE"""),"Pizza") -> Pizza | BA10: =IFERROR(__xludf.DUMMYFUNCTION("""COMPUTED_VALUE"""),55.0) -> 55 | BB10: =IFERROR(__xludf.DUMMYFUNCTION("""COMPUTED_VALUE"""),"QSR - Pizza Delivery") -> QSR - Pizza Delivery | BC10: =IFERROR(__xludf.DUMMYFUNCTION("""COMPUTED_VALUE"""),"Regional") -> Regional | BE10: =IFERROR(__xludf.DUMMYFUNCTION("""COMPUTED_VALUE"""),70.0) -> 70 | BF10: =IFERROR(__xludf.DUMMYFUNCTION("""COMPUTED_VALUE"""),0.85) -> 0.85 | BG10: =IFERROR(__xludf.DUMMYFUNCTION("""COMPUTED_VALUE"""),"Alta aderência ao 3S: PDV atual não identificado. 3S oferece Kiosk nativo, Hub Delivery integrado e gestão centralizada multi-loja - diferenciais competitivos para expansão e redução de filas.") -> Alta aderência ao 3S: PDV atual não identificado. 3S oferece Kiosk nativo, Hub Delivery integrado e gestão centralizada multi-loja - diferenciais competitivos para expansão e redução de filas. | BH10: null | BI10: 0.4
A11: =IFERROR(__xludf.DUMMYFUNCTION("""COMPUTED_VALUE"""),"AMBROZINI") -> AMBROZINI | B11: =IFERROR(__xludf.DUMMYFUNCTION("""COMPUTED_VALUE"""),"João Biagiotti") -> João Biagiotti | C11: =IFERROR(__xludf.DUMMYFUNCTION("""COMPUTED_VALUE"""),"Diego Santos") -> Diego Santos | D11: =IFERROR(__xludf.DUMMYFUNCTION("""COMPUTED_VALUE"""),"1. Iniciado") -> 1. Iniciado | E11: =IFERROR(__xludf.DUMMYFUNCTION("""COMPUTED_VALUE"""),"Delivery - Aguardando retorno executivo") -> Delivery - Aguardando retorno executivo | F11: =IFERROR(__xludf.DUMMYFUNCTION("""COMPUTED_VALUE"""),"P") -> P | G11: =IFERROR(__xludf.DUMMYFUNCTION("""COMPUTED_VALUE"""),46119.0) -> 46119 | H11: =IFERROR(__xludf.DUMMYFUNCTION("""COMPUTED_VALUE"""),"Foi enviado mensagem para a coordenação para verificar a possibilidade de uma agenda e direcionamento ") -> Foi enviado mensagem para a coordenação para verificar a possibilidade de uma agenda e direcionamento | I11: =IFERROR(__xludf.DUMMYFUNCTION("""COMPUTED_VALUE"""),46120.46079829861) -> 46120.461 | AA11: =IFERROR(__xludf.DUMMYFUNCTION("""COMPUTED_VALUE"""),5.0) -> 5 | AB11: =IFERROR(__xludf.DUMMYFUNCTION("""COMPUTED_VALUE"""),"CE") -> CE | AC11: =IFERROR(__xludf.DUMMYFUNCTION("""COMPUTED_VALUE"""),"Sim") -> Sim | AD11: =IFERROR(__xludf.DUMMYFUNCTION("""COMPUTED_VALUE"""),"Ifood") -> Ifood | AM11: =IFERROR(__xludf.DUMMYFUNCTION("""COMPUTED_VALUE"""),"FY27") -> FY27 | AO11: =IFERROR(__xludf.DUMMYFUNCTION("""COMPUTED_VALUE"""),96.0) -> 96 | AP11: =IFERROR(__xludf.DUMMYFUNCTION("""COMPUTED_VALUE"""),"MG") -> MG | AQ11: =IFERROR(__xludf.DUMMYFUNCTION("""COMPUTED_VALUE"""),"EDUARDA HALABI") -> EDUARDA HALABI | AR11: =IFERROR(__xludf.DUMMYFUNCTION("""COMPUTED_VALUE"""),"DIEGO PINTO") -> DIEGO PINTO | AS11: =IFERROR(__xludf.DUMMYFUNCTION("""COMPUTED_VALUE"""),"FABIO DONATO") -> FABIO DONATO | AT11: =IFERROR(__xludf.DUMMYFUNCTION("""COMPUTED_VALUE"""),"GILSON JUNIOR") -> GILSON JUNIOR | AU11: =IFERROR(__xludf.DUMMYFUNCTION("""COMPUTED_VALUE"""),0.0) -> 0 | AV11: =IFERROR(__xludf.DUMMYFUNCTION("""COMPUTED_VALUE"""),0.0) -> 0 | AW11: =IFERROR(__xludf.DUMMYFUNCTION("""COMPUTED_VALUE"""),0.0) -> 0 | AX11: =IFERROR(__xludf.DUMMYFUNCTION("""COMPUTED_VALUE"""),0.0) -> 0 | AY11: =IFERROR(__xludf.DUMMYFUNCTION("""COMPUTED_VALUE"""),"Saipos Serviços De Software") -> Saipos Serviços De Software | AZ11: =IFERROR(__xludf.DUMMYFUNCTION("""COMPUTED_VALUE"""),"Brasileira") -> Brasileira | BA11: =IFERROR(__xludf.DUMMYFUNCTION("""COMPUTED_VALUE"""),65.0) -> 65 | BB11: =IFERROR(__xludf.DUMMYFUNCTION("""COMPUTED_VALUE"""),"Table Service - Self-Service Gourmet") -> Table Service - Self-Service Gourmet | BC11: =IFERROR(__xludf.DUMMYFUNCTION("""COMPUTED_VALUE"""),"Belo Horizonte/MG") -> Belo Horizonte/MG | BE11: =IFERROR(__xludf.DUMMYFUNCTION("""COMPUTED_VALUE"""),55.0) -> 55 | BF11: =IFERROR(__xludf.DUMMYFUNCTION("""COMPUTED_VALUE"""),0.65) -> 0.65 | BG11: =IFERROR(__xludf.DUMMYFUNCTION("""COMPUTED_VALUE"""),"Aderência forte ao 3S: PDV atual não identificado. 3S oferece PDV robusto, KDS integrado e mobilidade (3SGO) para gestão em tempo real - ideal para operações multi-canal.") -> Aderência forte ao 3S: PDV atual não identificado. 3S oferece PDV robusto, KDS integrado e mobilidade (3SGO) para gestão em tempo real - ideal para operações multi-canal. | BH11: null | BI11: 1
A12: =IFERROR(__xludf.DUMMYFUNCTION("""COMPUTED_VALUE"""),"AMERICAN ORIGINAL - CONTA MARCA") -> AMERICAN ORIGINAL - CONTA MARCA | B12: =IFERROR(__xludf.DUMMYFUNCTION("""COMPUTED_VALUE"""),"Lídia Esteves") -> Lídia Esteves | C12: =IFERROR(__xludf.DUMMYFUNCTION("""COMPUTED_VALUE"""),"Gabriela Roma") -> Gabriela Roma | D12: =IFERROR(__xludf.DUMMYFUNCTION("""COMPUTED_VALUE"""),"1. Iniciado") -> 1. Iniciado | F12: =IFERROR(__xludf.DUMMYFUNCTION("""COMPUTED_VALUE"""),"P") -> P | I12: =IFERROR(__xludf.DUMMYFUNCTION("""COMPUTED_VALUE"""),46140.610919548606) -> 46140.611 | AA12: =IFERROR(__xludf.DUMMYFUNCTION("""COMPUTED_VALUE"""),13.0) -> 13 | AB12: =IFERROR(__xludf.DUMMYFUNCTION("""COMPUTED_VALUE"""),"-") -> - | AC12: =IFERROR(__xludf.DUMMYFUNCTION("""COMPUTED_VALUE"""),"Sim") -> Sim | AD12: =IFERROR(__xludf.DUMMYFUNCTION("""COMPUTED_VALUE"""),"Ifood") -> Ifood | AM12: =IFERROR(__xludf.DUMMYFUNCTION("""COMPUTED_VALUE"""),"FY27") -> FY27 | AO12: =IFERROR(__xludf.DUMMYFUNCTION("""COMPUTED_VALUE"""),45553.0) -> 45553 | AP12: =IFERROR(__xludf.DUMMYFUNCTION("""COMPUTED_VALUE"""),"SC") -> SC | AQ12: =IFERROR(__xludf.DUMMYFUNCTION("""COMPUTED_VALUE"""),"MARCIO CHAGAS") -> MARCIO CHAGAS | AR12: =IFERROR(__xludf.DUMMYFUNCTION("""COMPUTED_VALUE"""),"ALEXSANDER ROCHA") -> ALEXSANDER ROCHA | AS12: =IFERROR(__xludf.DUMMYFUNCTION("""COMPUTED_VALUE"""),"FABIO DONATO") -> FABIO DONATO | AT12: =IFERROR(__xludf.DUMMYFUNCTION("""COMPUTED_VALUE"""),"CAMILA HOLANDA") -> CAMILA HOLANDA | AU12: =IFERROR(__xludf.DUMMYFUNCTION("""COMPUTED_VALUE"""),0.0) -> 0 | AV12: =IFERROR(__xludf.DUMMYFUNCTION("""COMPUTED_VALUE"""),0.0) -> 0 | AW12: =IFERROR(__xludf.DUMMYFUNCTION("""COMPUTED_VALUE"""),0.0) -> 0 | AX12: =IFERROR(__xludf.DUMMYFUNCTION("""COMPUTED_VALUE"""),0.0) -> 0 | AY12: =IFERROR(__xludf.DUMMYFUNCTION("""COMPUTED_VALUE"""),"Saipos Serviços De Software") -> Saipos Serviços De Software | AZ12: =IFERROR(__xludf.DUMMYFUNCTION("""COMPUTED_VALUE"""),"Lanches") -> Lanches | BA12: =IFERROR(__xludf.DUMMYFUNCTION("""COMPUTED_VALUE"""),55.0) -> 55 | BB12: =IFERROR(__xludf.DUMMYFUNCTION("""COMPUTED_VALUE"""),"Fast Casual - Hamburgueria") -> Fast Casual - Hamburgueria | BC12: =IFERROR(__xludf.DUMMYFUNCTION("""COMPUTED_VALUE"""),"Regional") -> Regional | BE12: =IFERROR(__xludf.DUMMYFUNCTION("""COMPUTED_VALUE"""),70.0) -> 70 | BF12: =IFERROR(__xludf.DUMMYFUNCTION("""COMPUTED_VALUE"""),0.8) -> 0.8 | BG12: =IFERROR(__xludf.DUMMYFUNCTION("""COMPUTED_VALUE"""),"Alta aderência ao 3S: PDV atual não identificado. 3S oferece Kiosk nativo, Hub Delivery integrado e gestão centralizada multi-loja - diferenciais competitivos para expansão e redução de filas.") -> Alta aderência ao 3S: PDV atual não identificado. 3S oferece Kiosk nativo, Hub Delivery integrado e gestão centralizada multi-loja - diferenciais competitivos para expansão e redução de filas. | BH12: null | BI12: 1
A13: =IFERROR(__xludf.DUMMYFUNCTION("""COMPUTED_VALUE"""),"ANGUS - CARNES E HAMBURGUERIA") -> ANGUS - CARNES E HAMBURGUERIA | B13: =IFERROR(__xludf.DUMMYFUNCTION("""COMPUTED_VALUE"""),"Lídia Esteves") -> Lídia Esteves | C13: =IFERROR(__xludf.DUMMYFUNCTION("""COMPUTED_VALUE"""),"Gabriela Roma") -> Gabriela Roma | D13: =IFERROR(__xludf.DUMMYFUNCTION("""COMPUTED_VALUE"""),"1. Iniciado") -> 1. Iniciado | E13: =IFERROR(__xludf.DUMMYFUNCTION("""COMPUTED_VALUE"""),"Delivery - Aguardando retorno executivo") -> Delivery - Aguardando retorno executivo | F13: =IFERROR(__xludf.DUMMYFUNCTION("""COMPUTED_VALUE"""),"P") -> P | G13: =IFERROR(__xludf.DUMMYFUNCTION("""COMPUTED_VALUE"""),46156.0) -> 46156 | H13: =IFERROR(__xludf.DUMMYFUNCTION("""COMPUTED_VALUE"""),"pedido de agenda com delivery") -> pedido de agenda com delivery | I13: =IFERROR(__xludf.DUMMYFUNCTION("""COMPUTED_VALUE"""),46156.69866701389) -> 46156.699 | AA13: =IFERROR(__xludf.DUMMYFUNCTION("""COMPUTED_VALUE"""),5.0) -> 5 | AB13: =IFERROR(__xludf.DUMMYFUNCTION("""COMPUTED_VALUE"""),"CE") -> CE | AC13: =IFERROR(__xludf.DUMMYFUNCTION("""COMPUTED_VALUE"""),"Sim") -> Sim | AD13: =IFERROR(__xludf.DUMMYFUNCTION("""COMPUTED_VALUE"""),"Mp Multipedidos") -> Mp Multipedidos | AM13: =IFERROR(__xludf.DUMMYFUNCTION("""COMPUTED_VALUE"""),"FY27") -> FY27 | AO13: =IFERROR(__xludf.DUMMYFUNCTION("""COMPUTED_VALUE"""),59.0) -> 59 | AP13: =IFERROR(__xludf.DUMMYFUNCTION("""COMPUTED_VALUE"""),"SC") -> SC | AQ13: =IFERROR(__xludf.DUMMYFUNCTION("""COMPUTED_VALUE"""),"MARCIO CHAGAS") -> MARCIO CHAGAS | AR13: =IFERROR(__xludf.DUMMYFUNCTION("""COMPUTED_VALUE"""),"CAMILA CASAGRANDE") -> CAMILA CASAGRANDE | AS13: =IFERROR(__xludf.DUMMYFUNCTION("""COMPUTED_VALUE"""),"FABIO DONATO") -> FABIO DONATO | AT13: =IFERROR(__xludf.DUMMYFUNCTION("""COMPUTED_VALUE"""),"CAMILA HOLANDA") -> CAMILA HOLANDA | AU13: =IFERROR(__xludf.DUMMYFUNCTION("""COMPUTED_VALUE"""),0.0) -> 0 | AV13: =IFERROR(__xludf.DUMMYFUNCTION("""COMPUTED_VALUE"""),0.0) -> 0 | AW13: =IFERROR(__xludf.DUMMYFUNCTION("""COMPUTED_VALUE"""),0.0) -> 0 | AX13: =IFERROR(__xludf.DUMMYFUNCTION("""COMPUTED_VALUE"""),0.0) -> 0 | AZ13: =IFERROR(__xludf.DUMMYFUNCTION("""COMPUTED_VALUE"""),"Marmita") -> Marmita | BA13: =IFERROR(__xludf.DUMMYFUNCTION("""COMPUTED_VALUE"""),70.0) -> 70 | BB13: =IFERROR(__xludf.DUMMYFUNCTION("""COMPUTED_VALUE"""),"Fast Casual - Burgers Premium") -> Fast Casual - Burgers Premium | BC13: =IFERROR(__xludf.DUMMYFUNCTION("""COMPUTED_VALUE"""),"Regional") -> Regional | BE13: =IFERROR(__xludf.DUMMYFUNCTION("""COMPUTED_VALUE"""),70.0) -> 70 | BF13: =IFERROR(__xludf.DUMMYFUNCTION("""COMPUTED_VALUE"""),0.75) -> 0.75 | BG13: =IFERROR(__xludf.DUMMYFUNCTION("""COMPUTED_VALUE"""),"Aderência forte ao 3S: PDV atual não identificado. 3S oferece PDV robusto, KDS integrado e mobilidade (3SGO) para gestão em tempo real - ideal para operações multi-canal.") -> Aderência forte ao 3S: PDV atual não identificado. 3S oferece PDV robusto, KDS integrado e mobilidade (3SGO) para gestão em tempo real - ideal para operações multi-canal. | BH13: Mp Multipedidos | BI13: 0.57894737
A14: =IFERROR(__xludf.DUMMYFUNCTION("""COMPUTED_VALUE"""),"ARNALDOS LANCHES - NIVEL MARCA") -> ARNALDOS LANCHES - NIVEL MARCA | B14: =IFERROR(__xludf.DUMMYFUNCTION("""COMPUTED_VALUE"""),"Lídia Esteves") -> Lídia Esteves | C14: =IFERROR(__xludf.DUMMYFUNCTION("""COMPUTED_VALUE"""),"Gabriela Roma") -> Gabriela Roma | D14: =IFERROR(__xludf.DUMMYFUNCTION("""COMPUTED_VALUE"""),"1. Iniciado") -> 1. Iniciado | E14: =IFERROR(__xludf.DUMMYFUNCTION("""COMPUTED_VALUE"""),"Delivery - Aguardando retorno executivo") -> Delivery - Aguardando retorno executivo | F14: =IFERROR(__xludf.DUMMYFUNCTION("""COMPUTED_VALUE"""),"P") -> P | G14: =IFERROR(__xludf.DUMMYFUNCTION("""COMPUTED_VALUE"""),46156.0) -> 46156 | H14: =IFERROR(__xludf.DUMMYFUNCTION("""COMPUTED_VALUE"""),"pedido de abertura de portas pelo exec de delivery") -> pedido de abertura de portas pelo exec de delivery | I14: =IFERROR(__xludf.DUMMYFUNCTION("""COMPUTED_VALUE"""),46156.70339043981) -> 46156.703 | AA14: =IFERROR(__xludf.DUMMYFUNCTION("""COMPUTED_VALUE"""),5.0) -> 5 | AB14: =IFERROR(__xludf.DUMMYFUNCTION("""COMPUTED_VALUE"""),"CE") -> CE | AC14: =IFERROR(__xludf.DUMMYFUNCTION("""COMPUTED_VALUE"""),"Sim") -> Sim | AD14: =IFERROR(__xludf.DUMMYFUNCTION("""COMPUTED_VALUE"""),"Sagres Automação Comercial") -> Sagres Automação Comercial | AM14: =IFERROR(__xludf.DUMMYFUNCTION("""COMPUTED_VALUE"""),"FY27") -> FY27 | AO14: =IFERROR(__xludf.DUMMYFUNCTION("""COMPUTED_VALUE"""),59.0) -> 59 | AP14: =IFERROR(__xludf.DUMMYFUNCTION("""COMPUTED_VALUE"""),"PR") -> PR | AQ14: =IFERROR(__xludf.DUMMYFUNCTION("""COMPUTED_VALUE"""),"LUIZ FILHO") -> LUIZ FILHO | AR14: =IFERROR(__xludf.DUMMYFUNCTION("""COMPUTED_VALUE"""),"HELOISA SANTOS") -> HELOISA SANTOS | AS14: =IFERROR(__xludf.DUMMYFUNCTION("""COMPUTED_VALUE"""),"FABIO DONATO") -> FABIO DONATO | AT14: =IFERROR(__xludf.DUMMYFUNCTION("""COMPUTED_VALUE"""),"MURILO NAGASHIMA") -> MURILO NAGASHIMA | AU14: =IFERROR(__xludf.DUMMYFUNCTION("""COMPUTED_VALUE"""),0.0) -> 0 | AV14: =IFERROR(__xludf.DUMMYFUNCTION("""COMPUTED_VALUE"""),0.0) -> 0 | AW14: =IFERROR(__xludf.DUMMYFUNCTION("""COMPUTED_VALUE"""),0.0) -> 0 | AX14: =IFERROR(__xludf.DUMMYFUNCTION("""COMPUTED_VALUE"""),0.0) -> 0 | AZ14: =IFERROR(__xludf.DUMMYFUNCTION("""COMPUTED_VALUE"""),"Lanches") -> Lanches | BA14: =IFERROR(__xludf.DUMMYFUNCTION("""COMPUTED_VALUE"""),"") | BB14: =IFERROR(__xludf.DUMMYFUNCTION("""COMPUTED_VALUE"""),"") | BC14: =IFERROR(__xludf.DUMMYFUNCTION("""COMPUTED_VALUE"""),"") | BD14: =IFERROR(__xludf.DUMMYFUNCTION("""COMPUTED_VALUE"""),"") | BE14: =IFERROR(__xludf.DUMMYFUNCTION("""COMPUTED_VALUE"""),"") | BF14: =IFERROR(__xludf.DUMMYFUNCTION("""COMPUTED_VALUE"""),"") | BG14: =IFERROR(__xludf.DUMMYFUNCTION("""COMPUTED_VALUE"""),"") | BH14: Sagres Automação Comercial | BI14: 1
A15: =IFERROR(__xludf.DUMMYFUNCTION("""COMPUTED_VALUE"""),"ARO TEMAKERIA DELIVERY") -> ARO TEMAKERIA DELIVERY | B15: =IFERROR(__xludf.DUMMYFUNCTION("""COMPUTED_VALUE"""),"João Biagiotti") -> João Biagiotti | C15: =IFERROR(__xludf.DUMMYFUNCTION("""COMPUTED_VALUE"""),"Diego Santos") -> Diego Santos | D15: =IFERROR(__xludf.DUMMYFUNCTION("""COMPUTED_VALUE"""),"0. Não Iniciado") -> 0. Não Iniciado | F15: =IFERROR(__xludf.DUMMYFUNCTION("""COMPUTED_VALUE"""),"P") -> P | AA15: =IFERROR(__xludf.DUMMYFUNCTION("""COMPUTED_VALUE"""),7.0) -> 7 | AB15: =IFERROR(__xludf.DUMMYFUNCTION("""COMPUTED_VALUE"""),"CE") -> CE | AC15: =IFERROR(__xludf.DUMMYFUNCTION("""COMPUTED_VALUE"""),"Sim") -> Sim | AD15: =IFERROR(__xludf.DUMMYFUNCTION("""COMPUTED_VALUE"""),"Ifood") -> Ifood | AM15: =IFERROR(__xludf.DUMMYFUNCTION("""COMPUTED_VALUE"""),"FY27") -> FY27 | AO15: =IFERROR(__xludf.DUMMYFUNCTION("""COMPUTED_VALUE"""),45553.0) -> 45553 | AP15: =IFERROR(__xludf.DUMMYFUNCTION("""COMPUTED_VALUE"""),"SP") -> SP | AQ15: =IFERROR(__xludf.DUMMYFUNCTION("""COMPUTED_VALUE"""),"ANDRE PARAIZO") -> ANDRE PARAIZO | AR15: =IFERROR(__xludf.DUMMYFUNCTION("""COMPUTED_VALUE"""),"DIOGO NEPOMUCENO") -> DIOGO NEPOMUCENO | AS15: =IFERROR(__xludf.DUMMYFUNCTION("""COMPUTED_VALUE"""),"ALAN HADDAD") -> ALAN HADDAD | AT15: =IFERROR(__xludf.DUMMYFUNCTION("""COMPUTED_VALUE"""),"GABRIEL PERES") -> GABRIEL PERES | AU15: =IFERROR(__xludf.DUMMYFUNCTION("""COMPUTED_VALUE"""),0.0) -> 0 | AV15: =IFERROR(__xludf.DUMMYFUNCTION("""COMPUTED_VALUE"""),0.0) -> 0 | AW15: =IFERROR(__xludf.DUMMYFUNCTION("""COMPUTED_VALUE"""),0.0) -> 0 | AX15: =IFERROR(__xludf.DUMMYFUNCTION("""COMPUTED_VALUE"""),0.0) -> 0 | AY15: =IFERROR(__xludf.DUMMYFUNCTION("""COMPUTED_VALUE"""),"Anota Ai Solucoes Digitais S/a") -> Anota Ai Solucoes Digitais S/a | AZ15: =IFERROR(__xludf.DUMMYFUNCTION("""COMPUTED_VALUE"""),"Japonesa") -> Japonesa | BA15: =IFERROR(__xludf.DUMMYFUNCTION("""COMPUTED_VALUE"""),60.0) -> 60 | BB15: =IFERROR(__xludf.DUMMYFUNCTION("""COMPUTED_VALUE"""),"Delivery First - Temakeria") -> Delivery First - Temakeria | BC15: =IFERROR(__xludf.DUMMYFUNCTION("""COMPUTED_VALUE"""),"Regional") -> Regional | BE15: =IFERROR(__xludf.DUMMYFUNCTION("""COMPUTED_VALUE"""),45.0) -> 45 | BF15: =IFERROR(__xludf.DUMMYFUNCTION("""COMPUTED_VALUE"""),0.5) -> 0.5 | BG15: =IFERROR(__xludf.DUMMYFUNCTION("""COMPUTED_VALUE"""),"Aderência moderada ao 3S: PDV atual não identificado. 3S pode agregar valor com padronização multi-loja e integração delivery, mas necessário Discovery para validar fit completo.") -> Aderência moderada ao 3S: PDV atual não identificado. 3S pode agregar valor com padronização multi-loja e integração delivery, mas necessário Discovery para validar fit completo. | BH15: Anota Ai Solucoes Digitais S/a | BI15: 0.66666667
A16: =IFERROR(__xludf.DUMMYFUNCTION("""COMPUTED_VALUE"""),"BABY BEEF EXPRESS") -> BABY BEEF EXPRESS | B16: =IFERROR(__xludf.DUMMYFUNCTION("""COMPUTED_VALUE"""),"João Biagiotti") -> João Biagiotti | C16: =IFERROR(__xludf.DUMMYFUNCTION("""COMPUTED_VALUE"""),"Diego Santos") -> Diego Santos | D16: =IFERROR(__xludf.DUMMYFUNCTION("""COMPUTED_VALUE"""),"2. Primeiro Contato com a marca") -> 2. Primeiro Contato com a marca | E16: =IFERROR(__xludf.DUMMYFUNCTION("""COMPUTED_VALUE"""),"Delivery - Conciliação agenda com parceiro") -> Delivery - Conciliação agenda com parceiro | F16: =IFERROR(__xludf.DUMMYFUNCTION("""COMPUTED_VALUE"""),"P") -> P | G16: =IFERROR(__xludf.DUMMYFUNCTION("""COMPUTED_VALUE"""),46134.0) -> 46134 | H16: =IFERROR(__xludf.DUMMYFUNCTION("""COMPUTED_VALUE"""),"Valeria (coord) informou que o gerrente esta de férias, assim que voltar iremos agendar uma reunião com os mesmos") -> Valeria (coord) informou que o gerrente esta de férias, assim que voltar iremos agendar uma reunião com os mesmos | I16: =IFERROR(__xludf.DUMMYFUNCTION("""COMPUTED_VALUE"""),46134.455329895834) -> 46134.455 | J16: =IFERROR(__xludf.DUMMYFUNCTION("""COMPUTED_VALUE"""),46134.45850049768) -> 46134.459 | AA16: =IFERROR(__xludf.DUMMYFUNCTION("""COMPUTED_VALUE"""),13.0) -> 13 | AB16: =IFERROR(__xludf.DUMMYFUNCTION("""COMPUTED_VALUE"""),"CE") -> CE | AC16: =IFERROR(__xludf.DUMMYFUNCTION("""COMPUTED_VALUE"""),"Sim") -> Sim | AD16: =IFERROR(__xludf.DUMMYFUNCTION("""COMPUTED_VALUE"""),"Ifood") -> Ifood | AM16: =IFERROR(__xludf.DUMMYFUNCTION("""COMPUTED_VALUE"""),"FY27") -> FY27 | AO16: =IFERROR(__xludf.DUMMYFUNCTION("""COMPUTED_VALUE"""),81.0) -> 81 | AP16: =IFERROR(__xludf.DUMMYFUNCTION("""COMPUTED_VALUE"""),"BA") -> BA | AQ16: =IFERROR(__xludf.DUMMYFUNCTION("""COMPUTED_VALUE"""),"VIDOLIN EDUARDO") -> VIDOLIN EDUARDO | AR16: =IFERROR(__xludf.DUMMYFUNCTION("""COMPUTED_VALUE"""),"VALERIA VASCONCELOS") -> VALERIA VASCONCELOS | AS16: =IFERROR(__xludf.DUMMYFUNCTION("""COMPUTED_VALUE"""),"THIAGO ROMAGNOLE") -> THIAGO ROMAGNOLE | AT16: =IFERROR(__xludf.DUMMYFUNCTION("""COMPUTED_VALUE"""),"EDUARDO VAZ") -> EDUARDO VAZ | AU16: =IFERROR(__xludf.DUMMYFUNCTION("""COMPUTED_VALUE"""),0.0) -> 0 | AV16: =IFERROR(__xludf.DUMMYFUNCTION("""COMPUTED_VALUE"""),0.0) -> 0 | AW16: =IFERROR(__xludf.DUMMYFUNCTION("""COMPUTED_VALUE"""),0.0) -> 0 | AX16: =IFERROR(__xludf.DUMMYFUNCTION("""COMPUTED_VALUE"""),0.0) -> 0 | AZ16: =IFERROR(__xludf.DUMMYFUNCTION("""COMPUTED_VALUE"""),"Lanches") -> Lanches | BA16: =IFERROR(__xludf.DUMMYFUNCTION("""COMPUTED_VALUE"""),60.0) -> 60 | BB16: =IFERROR(__xludf.DUMMYFUNCTION("""COMPUTED_VALUE"""),"Fast Casual - Grelhados") -> Fast Casual - Grelhados | BC16: =IFERROR(__xludf.DUMMYFUNCTION("""COMPUTED_VALUE"""),"Salvador/BA (shoppings)") -> Salvador/BA (shoppings) | BE16: =IFERROR(__xludf.DUMMYFUNCTION("""COMPUTED_VALUE"""),65.0) -> 65 | BF16: =IFERROR(__xludf.DUMMYFUNCTION("""COMPUTED_VALUE"""),0.75) -> 0.75 | BG16: =IFERROR(__xludf.DUMMYFUNCTION("""COMPUTED_VALUE"""),"Aderência forte ao 3S: PDV atual não identificado. 3S oferece PDV robusto, KDS integrado e mobilidade (3SGO) para gestão em tempo real - ideal para operações multi-canal.") -> Aderência forte ao 3S: PDV atual não identificado. 3S oferece PDV robusto, KDS integrado e mobilidade (3SGO) para gestão em tempo real - ideal para operações multi-canal. | BH16: null | BI16: 0.57142857
A17: =IFERROR(__xludf.DUMMYFUNCTION("""COMPUTED_VALUE"""),"BANZAI ES") -> BANZAI ES | B17: =IFERROR(__xludf.DUMMYFUNCTION("""COMPUTED_VALUE"""),"Lídia Esteves") -> Lídia Esteves | C17: =IFERROR(__xludf.DUMMYFUNCTION("""COMPUTED_VALUE"""),"Gabriela Roma") -> Gabriela Roma | D17: =IFERROR(__xludf.DUMMYFUNCTION("""COMPUTED_VALUE"""),"0. Não Iniciado") -> 0. Não Iniciado | F17: =IFERROR(__xludf.DUMMYFUNCTION("""COMPUTED_VALUE"""),"P") -> P | AA17: =IFERROR(__xludf.DUMMYFUNCTION("""COMPUTED_VALUE"""),7.0) -> 7 | AB17: =IFERROR(__xludf.DUMMYFUNCTION("""COMPUTED_VALUE"""),"CE") -> CE | AC17: =IFERROR(__xludf.DUMMYFUNCTION("""COMPUTED_VALUE"""),"Sim") -> Sim | AD17: =IFERROR(__xludf.DUMMYFUNCTION("""COMPUTED_VALUE"""),"Ifood") -> Ifood | AM17: =IFERROR(__xludf.DUMMYFUNCTION("""COMPUTED_VALUE"""),"FY27") -> FY27 | AO17: =IFERROR(__xludf.DUMMYFUNCTION("""COMPUTED_VALUE"""),45553.0) -> 45553 | AP17: =IFERROR(__xludf.DUMMYFUNCTION("""COMPUTED_VALUE"""),"ES") -> ES | AQ17: =IFERROR(__xludf.DUMMYFUNCTION("""COMPUTED_VALUE"""),"LORENA PACHECO") -> LORENA PACHECO | AR17: =IFERROR(__xludf.DUMMYFUNCTION("""COMPUTED_VALUE"""),"THAYNA MARINS") -> THAYNA MARINS | AS17: =IFERROR(__xludf.DUMMYFUNCTION("""COMPUTED_VALUE"""),"FABIO DONATO") -> FABIO DONATO | AT17: =IFERROR(__xludf.DUMMYFUNCTION("""COMPUTED_VALUE"""),"GILSON JUNIOR") -> GILSON JUNIOR | AU17: =IFERROR(__xludf.DUMMYFUNCTION("""COMPUTED_VALUE"""),0.0) -> 0 | AV17: =IFERROR(__xludf.DUMMYFUNCTION("""COMPUTED_VALUE"""),0.0) -> 0 | AW17: =IFERROR(__xludf.DUMMYFUNCTION("""COMPUTED_VALUE"""),0.0) -> 0 | AX17: =IFERROR(__xludf.DUMMYFUNCTION("""COMPUTED_VALUE"""),0.0) -> 0 | AY17: =IFERROR(__xludf.DUMMYFUNCTION("""COMPUTED_VALUE"""),"Tigoo Serviços Ltda.") -> Tigoo Serviços Ltda. | AZ17: =IFERROR(__xludf.DUMMYFUNCTION("""COMPUTED_VALUE"""),"Japonesa") -> Japonesa | BA17: =IFERROR(__xludf.DUMMYFUNCTION("""COMPUTED_VALUE"""),65.0) -> 65 | BB17: =IFERROR(__xludf.DUMMYFUNCTION("""COMPUTED_VALUE"""),"Fast Casual - Comida Japonesa") -> Fast Casual - Comida Japonesa | BC17: =IFERROR(__xludf.DUMMYFUNCTION("""COMPUTED_VALUE"""),"Espírito Santo") -> Espírito Santo | BE17: =IFERROR(__xludf.DUMMYFUNCTION("""COMPUTED_VALUE"""),70.0) -> 70 | BF17: =IFERROR(__xludf.DUMMYFUNCTION("""COMPUTED_VALUE"""),0.75) -> 0.75 | BG17: =IFERROR(__xludf.DUMMYFUNCTION("""COMPUTED_VALUE"""),"Aderência forte ao 3S: PDV atual não identificado. 3S oferece PDV robusto, KDS integrado e mobilidade (3SGO) para gestão em tempo real - ideal para operações multi-canal.") -> Aderência forte ao 3S: PDV atual não identificado. 3S oferece PDV robusto, KDS integrado e mobilidade (3SGO) para gestão em tempo real - ideal para operações multi-canal. | BH17: Tigoo Serviços Ltda. | BI17: 0.5
A18: =IFERROR(__xludf.DUMMYFUNCTION("""COMPUTED_VALUE"""),"BAR DO ELIAS") -> BAR DO ELIAS | B18: =IFERROR(__xludf.DUMMYFUNCTION("""COMPUTED_VALUE"""),"Lídia Esteves") -> Lídia Esteves | C18: =IFERROR(__xludf.DUMMYFUNCTION("""COMPUTED_VALUE"""),"Gabriela Roma") -> Gabriela Roma | D18: =IFERROR(__xludf.DUMMYFUNCTION("""COMPUTED_VALUE"""),"1. Iniciado") -> 1. Iniciado | E18: =IFERROR(__xludf.DUMMYFUNCTION("""COMPUTED_VALUE"""),"Delivery - Aguardando retorno / Conciliação agenda") -> Delivery - Aguardando retorno / Conciliação agenda | F18: =IFERROR(__xludf.DUMMYFUNCTION("""COMPUTED_VALUE"""),"P") -> P | I18: =IFERROR(__xludf.DUMMYFUNCTION("""COMPUTED_VALUE"""),46122.672642314814) -> 46122.673 | AA18: =IFERROR(__xludf.DUMMYFUNCTION("""COMPUTED_VALUE"""),8.0) -> 8 | AB18: =IFERROR(__xludf.DUMMYFUNCTION("""COMPUTED_VALUE"""),"CE") -> CE | AC18: =IFERROR(__xludf.DUMMYFUNCTION("""COMPUTED_VALUE"""),"Sim") -> Sim | AD18: =IFERROR(__xludf.DUMMYFUNCTION("""COMPUTED_VALUE"""),"Ifood") -> Ifood | AM18: =IFERROR(__xludf.DUMMYFUNCTION("""COMPUTED_VALUE"""),"FY27") -> FY27 | AO18: =IFERROR(__xludf.DUMMYFUNCTION("""COMPUTED_VALUE"""),45553.0) -> 45553 | AP18: =IFERROR(__xludf.DUMMYFUNCTION("""COMPUTED_VALUE"""),"RJ") -> RJ | AQ18: =IFERROR(__xludf.DUMMYFUNCTION("""COMPUTED_VALUE"""),"ANA SALLES") -> ANA SALLES | AR18: =IFERROR(__xludf.DUMMYFUNCTION("""COMPUTED_VALUE"""),"MARCELLA BRAGA") -> MARCELLA BRAGA | AS18: =IFERROR(__xludf.DUMMYFUNCTION("""COMPUTED_VALUE"""),"NATHALIE MERTENS") -> NATHALIE MERTENS | AT18: =IFERROR(__xludf.DUMMYFUNCTION("""COMPUTED_VALUE"""),"NATALIA COUTINHO") -> NATALIA COUTINHO | AU18: =IFERROR(__xludf.DUMMYFUNCTION("""COMPUTED_VALUE"""),0.0) -> 0 | AV18: =IFERROR(__xludf.DUMMYFUNCTION("""COMPUTED_VALUE"""),0.0) -> 0 | AW18: =IFERROR(__xludf.DUMMYFUNCTION("""COMPUTED_VALUE"""),0.0) -> 0 | AX18: =IFERROR(__xludf.DUMMYFUNCTION("""COMPUTED_VALUE"""),0.0) -> 0 | AZ18: =IFERROR(__xludf.DUMMYFUNCTION("""COMPUTED_VALUE"""),"Árabe") -> Árabe | BA18: =IFERROR(__xludf.DUMMYFUNCTION("""COMPUTED_VALUE"""),75.0) -> 75 | BB18: =IFERROR(__xludf.DUMMYFUNCTION("""COMPUTED_VALUE"""),"Table Service - Boteco") -> Table Service - Boteco | BC18: =IFERROR(__xludf.DUMMYFUNCTION("""COMPUTED_VALUE"""),"Regional") -> Regional | BE18: =IFERROR(__xludf.DUMMYFUNCTION("""COMPUTED_VALUE"""),55.0) -> 55 | BF18: =IFERROR(__xludf.DUMMYFUNCTION("""COMPUTED_VALUE"""),0.65) -> 0.65 | BG18: =IFERROR(__xludf.DUMMYFUNCTION("""COMPUTED_VALUE"""),"Aderência forte ao 3S: PDV atual não identificado. 3S oferece PDV robusto, KDS integrado e mobilidade (3SGO) para gestão em tempo real - ideal para operações multi-canal.") -> Aderência forte ao 3S: PDV atual não identificado. 3S oferece PDV robusto, KDS integrado e mobilidade (3SGO) para gestão em tempo real - ideal para operações multi-canal.
A19: =IFERROR(__xludf.DUMMYFUNCTION("""COMPUTED_VALUE"""),"BB DOG") -> BB DOG | B19: =IFERROR(__xludf.DUMMYFUNCTION("""COMPUTED_VALUE"""),"Lídia Esteves") -> Lídia Esteves | C19: =IFERROR(__xludf.DUMMYFUNCTION("""COMPUTED_VALUE"""),"Gabriela Roma") -> Gabriela Roma | D19: =IFERROR(__xludf.DUMMYFUNCTION("""COMPUTED_VALUE"""),"0. Não Iniciado") -> 0. Não Iniciado | F19: =IFERROR(__xludf.DUMMYFUNCTION("""COMPUTED_VALUE"""),"P") -> P | AA19: =IFERROR(__xludf.DUMMYFUNCTION("""COMPUTED_VALUE"""),6.0) -> 6 | AB19: =IFERROR(__xludf.DUMMYFUNCTION("""COMPUTED_VALUE"""),"CE") -> CE | AC19: =IFERROR(__xludf.DUMMYFUNCTION("""COMPUTED_VALUE"""),"Sim") -> Sim | AD19: =IFERROR(__xludf.DUMMYFUNCTION("""COMPUTED_VALUE"""),"Ifood") -> Ifood | AM19: =IFERROR(__xludf.DUMMYFUNCTION("""COMPUTED_VALUE"""),"FY27") -> FY27 | AO19: =IFERROR(__xludf.DUMMYFUNCTION("""COMPUTED_VALUE"""),45553.0) -> 45553 | AP19: =IFERROR(__xludf.DUMMYFUNCTION("""COMPUTED_VALUE"""),"SP") -> SP | AQ19: =IFERROR(__xludf.DUMMYFUNCTION("""COMPUTED_VALUE"""),"EMILLY BIASI") -> EMILLY BIASI | AR19: =IFERROR(__xludf.DUMMYFUNCTION("""COMPUTED_VALUE"""),"MONICA VICTORIO") -> MONICA VICTORIO | AS19: =IFERROR(__xludf.DUMMYFUNCTION("""COMPUTED_VALUE"""),"ALAN HADDAD") -> ALAN HADDAD | AT19: =IFERROR(__xludf.DUMMYFUNCTION("""COMPUTED_VALUE"""),"ISABELA DINIZ") -> ISABELA DINIZ | AU19: =IFERROR(__xludf.DUMMYFUNCTION("""COMPUTED_VALUE"""),0.0) -> 0 | AV19: =IFERROR(__xludf.DUMMYFUNCTION("""COMPUTED_VALUE"""),0.0) -> 0 | AW19: =IFERROR(__xludf.DUMMYFUNCTION("""COMPUTED_VALUE"""),0.0) -> 0 | AX19: =IFERROR(__xludf.DUMMYFUNCTION("""COMPUTED_VALUE"""),0.0) -> 0 | AZ19: =IFERROR(__xludf.DUMMYFUNCTION("""COMPUTED_VALUE"""),"Lanches") -> Lanches | BA19: =IFERROR(__xludf.DUMMYFUNCTION("""COMPUTED_VALUE"""),25.0) -> 25 | BB19: =IFERROR(__xludf.DUMMYFUNCTION("""COMPUTED_VALUE"""),"QSR - Hot Dog") -> QSR - Hot Dog | BC19: =IFERROR(__xludf.DUMMYFUNCTION("""COMPUTED_VALUE"""),"Regional") -> Regional | BE19: =IFERROR(__xludf.DUMMYFUNCTION("""COMPUTED_VALUE"""),70.0) -> 70 | BF19: =IFERROR(__xludf.DUMMYFUNCTION("""COMPUTED_VALUE"""),0.85) -> 0.85 | BG19: =IFERROR(__xludf.DUMMYFUNCTION("""COMPUTED_VALUE"""),"Alta aderência ao 3S: PDV atual não identificado. 3S oferece Kiosk nativo, Hub Delivery integrado e gestão centralizada multi-loja - diferenciais competitivos para expansão e redução de filas.") -> Alta aderência ao 3S: PDV atual não identificado. 3S oferece Kiosk nativo, Hub Delivery integrado e gestão centralizada multi-loja - diferenciais competitivos para expansão e redução de filas. | BH19: Saipos Serviços De Software | BI19: 1
A20: =IFERROR(__xludf.DUMMYFUNCTION("""COMPUTED_VALUE"""),"BELLA PIZZA") -> BELLA PIZZA | B20: =IFERROR(__xludf.DUMMYFUNCTION("""COMPUTED_VALUE"""),"João Biagiotti") -> João Biagiotti | C20: =IFERROR(__xludf.DUMMYFUNCTION("""COMPUTED_VALUE"""),"Diego Santos") -> Diego Santos | D20: =IFERROR(__xludf.DUMMYFUNCTION("""COMPUTED_VALUE"""),"0. Não Iniciado") -> 0. Não Iniciado | F20: =IFERROR(__xludf.DUMMYFUNCTION("""COMPUTED_VALUE"""),"P") -> P | AA20: =IFERROR(__xludf.DUMMYFUNCTION("""COMPUTED_VALUE"""),11.0) -> 11 | AB20: =IFERROR(__xludf.DUMMYFUNCTION("""COMPUTED_VALUE"""),"CE") -> CE | AC20: =IFERROR(__xludf.DUMMYFUNCTION("""COMPUTED_VALUE"""),"Sim") -> Sim | AD20: =IFERROR(__xludf.DUMMYFUNCTION("""COMPUTED_VALUE"""),"Ifood") -> Ifood | AM20: =IFERROR(__xludf.DUMMYFUNCTION("""COMPUTED_VALUE"""),"FY27") -> FY27 | AO20: =IFERROR(__xludf.DUMMYFUNCTION("""COMPUTED_VALUE"""),45553.0) -> 45553 | AP20: =IFERROR(__xludf.DUMMYFUNCTION("""COMPUTED_VALUE"""),"PB") -> PB | AQ20: =IFERROR(__xludf.DUMMYFUNCTION("""COMPUTED_VALUE"""),"ANA ARAUJO") -> ANA ARAUJO | AR20: =IFERROR(__xludf.DUMMYFUNCTION("""COMPUTED_VALUE"""),"TAINAR ALBUQUERQUE") -> TAINAR ALBUQUERQUE | AS20: =IFERROR(__xludf.DUMMYFUNCTION("""COMPUTED_VALUE"""),"THIAGO ROMAGNOLE") -> THIAGO ROMAGNOLE | AT20: =IFERROR(__xludf.DUMMYFUNCTION("""COMPUTED_VALUE"""),"ANDERSON LAUREANO") -> ANDERSON LAUREANO | AU20: =IFERROR(__xludf.DUMMYFUNCTION("""COMPUTED_VALUE"""),0.0) -> 0 | AV20: =IFERROR(__xludf.DUMMYFUNCTION("""COMPUTED_VALUE"""),0.0) -> 0 | AW20: =IFERROR(__xludf.DUMMYFUNCTION("""COMPUTED_VALUE"""),0.0) -> 0 | AX20: =IFERROR(__xludf.DUMMYFUNCTION("""COMPUTED_VALUE"""),0.0) -> 0 | AY20: =IFERROR(__xludf.DUMMYFUNCTION("""COMPUTED_VALUE"""),"Saipos Serviços De Software") -> Saipos Serviços De Software | AZ20: =IFERROR(__xludf.DUMMYFUNCTION("""COMPUTED_VALUE"""),"Pizza") -> Pizza | BA20: =IFERROR(__xludf.DUMMYFUNCTION("""COMPUTED_VALUE"""),70.0) -> 70 | BB20: =IFERROR(__xludf.DUMMYFUNCTION("""COMPUTED_VALUE"""),"Fast Casual - Pizzaria") -> Fast Casual - Pizzaria | BC20: =IFERROR(__xludf.DUMMYFUNCTION("""COMPUTED_VALUE"""),"Regional") -> Regional | BE20: =IFERROR(__xludf.DUMMYFUNCTION("""COMPUTED_VALUE"""),65.0) -> 65 | BF20: =IFERROR(__xludf.DUMMYFUNCTION("""COMPUTED_VALUE"""),0.75) -> 0.75 | BG20: =IFERROR(__xludf.DUMMYFUNCTION("""COMPUTED_VALUE"""),"Aderência forte ao 3S: PDV atual não identificado. 3S oferece PDV robusto, KDS integrado e mobilidade (3SGO) para gestão em tempo real - ideal para operações multi-canal.") -> Aderência forte ao 3S: PDV atual não identificado. 3S oferece PDV robusto, KDS integrado e mobilidade (3SGO) para gestão em tempo real - ideal para operações multi-canal. | BH20: Saipos Serviços De Software | BI20: 0.25
