Workbook

Sheet Simulador
B2: Simular linhas em amarelo>> | E2: Preço Padrão | G2: Cenário 2 | I2: Cenário 3 | O2: Ano 1 | P2: Ano 2 | Q2: Ano 3 | R2: Ano 4 | S2: Ano 5 | T2: Ano 6 | U2: Ano 7 | V2: Ano 8 | W2: Ano 9 | X2: Ano 10 | Z2: Total
B4: Perfil
C6: Estado | E6: SP | G6: SP | I6: SP
M7: Resumo -% Margem Bruta
C8: Tempo de contrato (meses) | E8: 60
M9: Cenário 1 | O9: =ResumoCenarios!D10 -> 0.48145511 | P9: =ResumoCenarios!E10 -> 0.76653124 | Q9: =ResumoCenarios!F10 -> 0.76653124 | R9: =ResumoCenarios!G10 -> 0.76653124 | S9: =ResumoCenarios!H10 -> 0.76653124 | T9: =ResumoCenarios!I10 -> 0 | U9: =ResumoCenarios!J10 -> 0 | V9: =ResumoCenarios!K10 -> 0 | ... X9: =ResumoCenarios!M10 -> 0 | Z9: =ResumoCenarios!O10 -> 0.70312091
C10: Restaurantes por marca atual | E10: 25
C11: Meses de implantação | E11: 2 | M11: Cenário 2 | O11: =ResumoCenarios!D21 -> 0 | P11: =ResumoCenarios!E21 -> 0 | Q11: =ResumoCenarios!F21 -> 0 | R11: =ResumoCenarios!G21 -> 0 | S11: =ResumoCenarios!H21 -> 0 | T11: =ResumoCenarios!I21 -> 0 | U11: =ResumoCenarios!J21 -> 0 | V11: =ResumoCenarios!K21 -> 0 | ... X11: =ResumoCenarios!M21 -> 0 | Z11: =ResumoCenarios!O21 -> 0
C12: Restaurantes por marca ao final do contrato | E12: 25
M13: Cenário 3 | O13: =ResumoCenarios!D32 -> 0 | P13: =ResumoCenarios!E32 -> 0 | Q13: =ResumoCenarios!F32 -> 0 | R13: =ResumoCenarios!G32 -> 0 | S13: =ResumoCenarios!H32 -> 0 | T13: =ResumoCenarios!I32 -> 0 | U13: =ResumoCenarios!J32 -> 0 | V13: =ResumoCenarios!K32 -> 0 | ... X13: =ResumoCenarios!M32 -> 0 | Z13: =ResumoCenarios!O32 -> 0
C14: Frequência de pedidos (mensal por Restaurante) | I14: =G14 -> 0
C16: AOV | I16: =G16 -> 0
C18: Irá usar nosso Payments? | E18: FALSE | G18: FALSE | I18: FALSE
B19: Produtos por Restaurante
C21: PDV
C22: Quantidade | E22: 1 | G22: 1 | I22: 1
C23: Preço | E23: 600 | G23: 500
C25: Serviços Adicionais
C26: Preço
C27: Implantação
C28: Preço | E28: =IF(E$29=TRUE,Premissas!$C$12,IF(E$30=TRUE,Premissas!$C$13,0)) -> 1622 | G28: =IF(G$29=TRUE,Premissas!$C$12,IF(G$30=TRUE,Premissas!$C$13,0)) -> 1622 | I28: =IF(I$29=TRUE,Premissas!$C$12,IF(I$30=TRUE,Premissas!$C$13,0)) -> 1622
C29: Loja grande e/ou instalação presencial | E29: FALSE | G29: FALSE | I29: FALSE
C30: Loja pequena e/ou instalação remota | E30: TRUE | G30: TRUE | I30: TRUE
C31: Set up
C32: Preço | E32: 3000 | G32: 3000 | I32: 3000
B34: Descontos
C36: Isenção de mensalidade
C37: Meses de isenção das primeiras Mensalidade
C38: e / ou | G38: e / ou | I38: e / ou
C39: Isenção de implantação (%) | E39: 0
C40: e / ou | G40: e / ou | I40: e / ou
C41: Isenção de set up | G41: FALSE | I41: FALSE
C42: e / ou | G42: e / ou | I42: e / ou
C43: Desconto no Total
C44: Desconto da mensalidade
C45: Meses com desconto
B47: Investimentos
C49: Investimento para o cliente
C50: Meses de investimento
C51: Valor mensal do investimento
...

Sheet ResumoCenarios
B3: Cenário 1 | D3: Ano 1 | E3: Ano 2 | F3: Ano 3 | G3: Ano 4 | H3: Ano 5 | I3: Ano 6 | J3: Ano 7 | K3: Ano 8 | L3: Ano 9 | M3: Ano 10 | O3: Total
B4: Lojas (EoP) | D4: ='Cenário 1'!D$7 -> 25 | E4: ='Cenário 1'!E$7 -> 25 | F4: ='Cenário 1'!F$7 -> 25 | G4: ='Cenário 1'!G$7 -> 25 | H4: ='Cenário 1'!H$7 -> 25 | I4: ='Cenário 1'!I$7 -> 0 | J4: ='Cenário 1'!J$7 -> 0 | K4: ='Cenário 1'!K$7 -> 0 | ... M4: ='Cenário 1'!M$7 -> 0 | O4: =MAX(D4:M4) -> 25
B5: Produtos (EoP) | D5: =SUM('Cenário 1'!D9) -> 25 | E5: =SUM('Cenário 1'!E9) -> 25 | F5: =SUM('Cenário 1'!F9) -> 25 | G5: =SUM('Cenário 1'!G9) -> 25 | H5: =SUM('Cenário 1'!H9) -> 25 | I5: =SUM('Cenário 1'!I9) -> 0 | J5: =SUM('Cenário 1'!J9) -> 0 | K5: =SUM('Cenário 1'!K9) -> 0 | ... M5: =SUM('Cenário 1'!M9) -> 0 | O5: =MAX(D5:M5) -> 25
B6: Pedidos | D6: ='Cenário 1'!D$11 -> 0 | E6: ='Cenário 1'!E$11 -> 0 | F6: ='Cenário 1'!F$11 -> 0 | G6: ='Cenário 1'!G$11 -> 0 | H6: ='Cenário 1'!H$11 -> 0 | I6: ='Cenário 1'!I$11 -> 0 | J6: ='Cenário 1'!J$11 -> 0 | K6: ='Cenário 1'!K$11 -> 0 | ... M6: ='Cenário 1'!M$11 -> 0 | O6: =SUM(D6:M6) -> 0
B7: GMV | D7: ='Cenário 1'!D$13 -> 0 | E7: ='Cenário 1'!E$13 -> 0 | F7: ='Cenário 1'!F$13 -> 0 | G7: ='Cenário 1'!G$13 -> 0 | H7: ='Cenário 1'!H$13 -> 0 | I7: ='Cenário 1'!I$13 -> 0 | J7: ='Cenário 1'!J$13 -> 0 | K7: ='Cenário 1'!K$13 -> 0 | ... M7: ='Cenário 1'!M$13 -> 0 | O7: =SUM(D7:M7) -> 0
B8: Receita | D8: ='Cenário 1'!D$29 -> 194328.12 | E8: ='Cenário 1'!E$29 -> 169830 | F8: ='Cenário 1'!F$29 -> 169830 | G8: ='Cenário 1'!G$29 -> 169830 | H8: ='Cenário 1'!H$29 -> 169830 | I8: ='Cenário 1'!I$29 -> 0 | J8: ='Cenário 1'!J$29 -> 0 | K8: ='Cenário 1'!K$29 -> 0 | ... M8: ='Cenário 1'!M$29 -> 0 | O8: =SUM(D8:M8) -> 873648.12
B9: Lucro Bruto (-) CAC | D9: ='Cenário 1'!D$46 -> 93560.269 | E9: ='Cenário 1'!E$46 -> 130180 | F9: ='Cenário 1'!F$46 -> 130180 | G9: ='Cenário 1'!G$46 -> 130180 | H9: ='Cenário 1'!H$46 -> 130180 | I9: ='Cenário 1'!I$46 -> 0 | J9: ='Cenário 1'!J$46 -> 0 | K9: ='Cenário 1'!K$46 -> 0 | ... M9: ='Cenário 1'!M$46 -> 0 | O9: =SUM(D9:M9) -> 614280.27
B10: % Margem Bruta | D10: =IFERROR(D9/D8,0) -> 0.48145511 | E10: =IFERROR(E9/E8,0) -> 0.76653124 | F10: =IFERROR(F9/F8,0) -> 0.76653124 | G10: =IFERROR(G9/G8,0) -> 0.76653124 | H10: =IFERROR(H9/H8,0) -> 0.76653124 | I10: =IFERROR(I9/I8,0) -> 0 | J10: =IFERROR(J9/J8,0) -> 0 | K10: =IFERROR(K9/K8,0) -> 0 | ... M10: =IFERROR(M9/M8,0) -> 0 | O10: =IFERROR(O9/O8,0) -> 0.70312091
B11: Breakeven | O11: ='Cenário 1'!$D$49 -> 2
B14: Cenário 2 | D14: Ano 1 | E14: Ano 2 | F14: Ano 3 | G14: Ano 4 | H14: Ano 5 | I14: Ano 6 | J14: Ano 7 | K14: Ano 8 | L14: Ano 9 | M14: Ano 10 | O14: Total
B15: Lojas (EoP) | D15: ='Cenário 2'!D$7 -> #DIV/0! | E15: ='Cenário 2'!E$7 -> #DIV/0! | F15: ='Cenário 2'!F$7 -> #DIV/0! | G15: ='Cenário 2'!G$7 -> #DIV/0! | H15: ='Cenário 2'!H$7 -> #DIV/0! | I15: ='Cenário 2'!I$7 -> #DIV/0! | J15: ='Cenário 2'!J$7 -> #DIV/0! | K15: ='Cenário 2'!K$7 -> #DIV/0! | ... M15: ='Cenário 2'!M$7 -> #DIV/0! | O15: =MAX(D15:M15) -> #DIV/0!
B16: Produtos (EoP) | D16: =SUM('Cenário 2'!D9) -> #DIV/0! | E16: =SUM('Cenário 2'!E9) -> #DIV/0! | F16: =SUM('Cenário 2'!F9) -> #DIV/0! | G16: =SUM('Cenário 2'!G9) -> #DIV/0! | H16: =SUM('Cenário 2'!H9) -> #DIV/0! | I16: =SUM('Cenário 2'!I9) -> #DIV/0! | J16: =SUM('Cenário 2'!J9) -> #DIV/0! | K16: =SUM('Cenário 2'!K9) -> #DIV/0! | ... M16: =SUM('Cenário 2'!M9) -> #DIV/0! | O16: =MAX(D16:M16) -> #DIV/0!
B17: Pedidos | D17: ='Cenário 2'!D$11 -> #DIV/0! | E17: ='Cenário 2'!E$11 -> #DIV/0! | F17: ='Cenário 2'!F$11 -> #DIV/0! | G17: ='Cenário 2'!G$11 -> #DIV/0! | H17: ='Cenário 2'!H$11 -> #DIV/0! | I17: ='Cenário 2'!I$11 -> #DIV/0! | J17: ='Cenário 2'!J$11 -> #DIV/0! | K17: ='Cenário 2'!K$11 -> #DIV/0! | ... M17: ='Cenário 2'!M$11 -> #DIV/0! | O17: =SUM(D17:M17) -> #DIV/0!
B18: GMV | D18: ='Cenário 2'!D$13 -> #DIV/0! | E18: ='Cenário 2'!E$13 -> #DIV/0! | F18: ='Cenário 2'!F$13 -> #DIV/0! | G18: ='Cenário 2'!G$13 -> #DIV/0! | H18: ='Cenário 2'!H$13 -> #DIV/0! | I18: ='Cenário 2'!I$13 -> #DIV/0! | J18: ='Cenário 2'!J$13 -> #DIV/0! | K18: ='Cenário 2'!K$13 -> #DIV/0! | ... M18: ='Cenário 2'!M$13 -> #DIV/0! | O18: =SUM(D18:M18) -> #DIV/0!
B19: Receita | D19: ='Cenário 2'!D$29 -> #DIV/0! | E19: ='Cenário 2'!E$29 -> #DIV/0! | F19: ='Cenário 2'!F$29 -> #DIV/0! | G19: ='Cenário 2'!G$29 -> #DIV/0! | H19: ='Cenário 2'!H$29 -> #DIV/0! | I19: ='Cenário 2'!I$29 -> #DIV/0! | J19: ='Cenário 2'!J$29 -> #DIV/0! | K19: ='Cenário 2'!K$29 -> #DIV/0! | ... M19: ='Cenário 2'!M$29 -> #DIV/0! | O19: =SUM(D19:M19) -> #DIV/0!
B20: Lucro Bruto (-) CAC | D20: ='Cenário 2'!D$46 -> #DIV/0! | E20: ='Cenário 2'!E$46 -> #DIV/0! | F20: ='Cenário 2'!F$46 -> #DIV/0! | G20: ='Cenário 2'!G$46 -> #DIV/0! | H20: ='Cenário 2'!H$46 -> #DIV/0! | I20: ='Cenário 2'!I$46 -> #DIV/0! | J20: ='Cenário 2'!J$46 -> #DIV/0! | K20: ='Cenário 2'!K$46 -> #DIV/0! | ... M20: ='Cenário 2'!M$46 -> #DIV/0! | O20: =SUM(D20:M20) -> #DIV/0!
B21: % Margem Bruta | D21: =IFERROR(D20/D19,0) -> 0 | E21: =IFERROR(E20/E19,0) -> 0 | F21: =IFERROR(F20/F19,0) -> 0 | G21: =IFERROR(G20/G19,0) -> 0 | H21: =IFERROR(H20/H19,0) -> 0 | I21: =IFERROR(I20/I19,0) -> 0 | J21: =IFERROR(J20/J19,0) -> 0 | K21: =IFERROR(K20/K19,0) -> 0 | ... M21: =IFERROR(M20/M19,0) -> 0 | O21: =IFERROR(O20/O19,0) -> 0
B22: Breakeven | O22: ='Cenário 2'!$D$49 -> #DIV/0!
B25: Cenário 3 | D25: Ano 1 | E25: Ano 2 | F25: Ano 3 | G25: Ano 4 | H25: Ano 5 | I25: Ano 6 | J25: Ano 7 | K25: Ano 8 | L25: Ano 9 | M25: Ano 10 | O25: Total
B26: Lojas (EoP) | D26: ='Cenário 3'!D$7 -> #DIV/0! | E26: ='Cenário 3'!E$7 -> #DIV/0! | F26: ='Cenário 3'!F$7 -> #DIV/0! | G26: ='Cenário 3'!G$7 -> #DIV/0! | H26: ='Cenário 3'!H$7 -> #DIV/0! | I26: ='Cenário 3'!I$7 -> #DIV/0! | J26: ='Cenário 3'!J$7 -> #DIV/0! | K26: ='Cenário 3'!K$7 -> #DIV/0! | ... M26: ='Cenário 3'!M$7 -> #DIV/0! | O26: =MAX(D26:M26) -> #DIV/0!
B27: Produtos (EoP) | D27: =SUM('Cenário 3'!D9) -> #DIV/0! | E27: =SUM('Cenário 3'!E9) -> #DIV/0! | F27: =SUM('Cenário 3'!F9) -> #DIV/0! | G27: =SUM('Cenário 3'!G9) -> #DIV/0! | H27: =SUM('Cenário 3'!H9) -> #DIV/0! | I27: =SUM('Cenário 3'!I9) -> #DIV/0! | J27: =SUM('Cenário 3'!J9) -> #DIV/0! | K27: =SUM('Cenário 3'!K9) -> #DIV/0! | ... M27: =SUM('Cenário 3'!M9) -> #DIV/0! | O27: =MAX(D27:M27) -> #DIV/0!
B28: Pedidos | D28: ='Cenário 3'!D$11 -> #DIV/0! | E28: ='Cenário 3'!E$11 -> #DIV/0! | F28: ='Cenário 3'!F$11 -> #DIV/0! | G28: ='Cenário 3'!G$11 -> #DIV/0! | H28: ='Cenário 3'!H$11 -> #DIV/0! | I28: ='Cenário 3'!I$11 -> #DIV/0! | J28: ='Cenário 3'!J$11 -> #DIV/0! | K28: ='Cenário 3'!K$11 -> #DIV/0! | ... M28: ='Cenário 3'!M$11 -> #DIV/0! | O28: =SUM(D28:M28) -> #DIV/0!
B29: GMV | D29: ='Cenário 3'!D$13 -> #DIV/0! | E29: ='Cenário 3'!E$13 -> #DIV/0! | F29: ='Cenário 3'!F$13 -> #DIV/0! | G29: ='Cenário 3'!G$13 -> #DIV/0! | H29: ='Cenário 3'!H$13 -> #DIV/0! | I29: ='Cenário 3'!I$13 -> #DIV/0! | J29: ='Cenário 3'!J$13 -> #DIV/0! | K29: ='Cenário 3'!K$13 -> #DIV/0! | ... M29: ='Cenário 3'!M$13 -> #DIV/0! | O29: =SUM(D29:M29) -> #DIV/0!
B30: Receita | D30: ='Cenário 3'!D$29 -> #DIV/0! | E30: ='Cenário 3'!E$29 -> #DIV/0! | F30: ='Cenário 3'!F$29 -> #DIV/0! | G30: ='Cenário 3'!G$29 -> #DIV/0! | H30: ='Cenário 3'!H$29 -> #DIV/0! | I30: ='Cenário 3'!I$29 -> #DIV/0! | J30: ='Cenário 3'!J$29 -> #DIV/0! | K30: ='Cenário 3'!K$29 -> #DIV/0! | ... M30: ='Cenário 3'!M$29 -> #DIV/0! | O30: =SUM(D30:M30) -> #DIV/0!
B31: Lucro Bruto (-) CAC | D31: ='Cenário 3'!D$46 -> #DIV/0! | E31: ='Cenário 3'!E$46 -> #DIV/0! | F31: ='Cenário 3'!F$46 -> #DIV/0! | G31: ='Cenário 3'!G$46 -> #DIV/0! | H31: ='Cenário 3'!H$46 -> #DIV/0! | I31: ='Cenário 3'!I$46 -> #DIV/0! | J31: ='Cenário 3'!J$46 -> #DIV/0! | K31: ='Cenário 3'!K$46 -> #DIV/0! | ... M31: ='Cenário 3'!M$46 -> #DIV/0! | O31: =SUM(D31:M31) -> #DIV/0!
B32: % Margem Bruta | D32: =IFERROR(D31/D30,0) -> 0 | E32: =IFERROR(E31/E30,0) -> 0 | F32: =IFERROR(F31/F30,0) -> 0 | G32: =IFERROR(G31/G30,0) -> 0 | H32: =IFERROR(H31/H30,0) -> 0 | I32: =IFERROR(I31/I30,0) -> 0 | J32: =IFERROR(J31/J30,0) -> 0 | K32: =IFERROR(K31/K30,0) -> 0 | ... M32: =IFERROR(M31/M30,0) -> 0 | O32: =IFERROR(O31/O30,0) -> 0
B33: Breakeven | O33: ='Cenário 3'!$D$49 -> #DIV/0!

Sheet Cenário 1
P1: 1 | Q1: =P1+1 -> 2 | R1: =Q1+1 -> 3 | S1: =R1+1 -> 4 | T1: =S1+1 -> 5 | U1: =T1+1 -> 6 | V1: =U1+1 -> 7 | W1: =V1+1 -> 8 | X1: =W1+1 -> 9 | ... ED1: =EC1+1 -> 119
O2: 1 | P2: =O2+1 -> 2 | Q2: =P2+1 -> 3 | R2: =Q2+1 -> 4 | S2: =R2+1 -> 5 | T2: =S2+1 -> 6 | U2: =T2+1 -> 7 | V2: =U2+1 -> 8 | W2: =V2+1 -> 9 | ... ED2: =EC2+1 -> 120
D3: Ano 1 | E3: Ano 2 | F3: Ano 3 | G3: Ano 4 | H3: Ano 5 | I3: Ano 6 | J3: Ano 7 | K3: Ano 8 | L3: Ano 9 | M3: Ano 10 | O3: Mês 1 | P3: Mês 2 | Q3: Mês 3 | R3: Mês 4 | S3: Mês 5 | T3: Mês 6 | U3: Mês 7 | V3: Mês 8 | W3: Mês 9 | X3: Mês 10 | Y3: Mês 11 | Z3: Mês 12 | AA3: Mês 13 | AB3: Mês 14 | AC3: Mês 15 | AD3: Mês 16 | AE3: Mês 17 | AF3: Mês 18 | AG3: Mês 19 | AH3: Mês 20 | AI3: Mês 21 | AJ3: Mês 22 | AK3: Mês 23 | AL3: Mês 24 | AM3: Mês 25 | AN3: Mês 26 | AO3: Mês 27 | AP3: Mês 28 | AQ3: Mês 29 | AR3: Mês 30 | AS3: Mês 31 | AT3: Mês 32 | AU3: Mês 33 | AV3: Mês 34 | AW3: Mês 35 | AX3: Mês 36 | AY3: Mês 37 | AZ3: Mês 38 | BA3: Mês 39 | BB3: Mês 40 | BC3: Mês 41 | BD3: Mês 42 | BE3: Mês 43 | BF3: Mês 44 | BG3: Mês 45 | BH3: Mês 46 | BI3: Mês 47 | BJ3: Mês 48 | BK3: Mês 49 | BL3: Mês 50 | BM3: Mês 51 | BN3: Mês 52 | BO3: Mês 53 | BP3: Mês 54 | BQ3: Mês 55 | BR3: Mês 56 | BS3: Mês 57 | BT3: Mês 58 | BU3: Mês 59 | BV3: Mês 60 | BW3: Mês 61 | BX3: Mês 62 | BY3: Mês 63 | BZ3: Mês 64 | CA3: Mês 65 | CB3: Mês 66 | CC3: Mês 67 | CD3: Mês 68 | CE3: Mês 69 | CF3: Mês 70 | CG3: Mês 71 | CH3: Mês 72 | CI3: Mês 73 | CJ3: Mês 74 | CK3: Mês 75 | CL3: Mês 76 | CM3: Mês 77 | CN3: Mês 78 | CO3: Mês 79 | CP3: Mês 80 | CQ3: Mês 81 | CR3: Mês 82 | CS3: Mês 83 | CT3: Mês 84 | CU3: Mês 85 | CV3: Mês 86 | CW3: Mês 87 | CX3: Mês 88 | CY3: Mês 89 | CZ3: Mês 90 | DA3: Mês 91 | DB3: Mês 92 | DC3: Mês 93 | DD3: Mês 94 | DE3: Mês 95 | DF3: Mês 96 | DG3: Mês 97 | DH3: Mês 98 | DI3: Mês 99 | DJ3: Mês 100 | DK3: Mês 101 | DL3: Mês 102 | DM3: Mês 103 | DN3: Mês 104 | DO3: Mês 105 | DP3: Mês 106 | DQ3: Mês 107 | DR3: Mês 108 | DS3: Mês 109 | DT3: Mês 110 | DU3: Mês 111 | DV3: Mês 112 | DW3: Mês 113 | DX3: Mês 114 | DY3: Mês 115 | DZ3: Mês 116 | EA3: Mês 117 | EB3: Mês 118 | EC3: Mês 119 | ED3: Mês 120
D4: Mês 12 | E4: Mês 24 | F4: Mês 36 | G4: Mês 48 | H4: Mês 60 | I4: Mês 72 | J4: Mês 84 | K4: Mês 96 | L4: Mês 108 | M4: Mês 120 | O4: Ano 1 | P4: Ano 1 | Q4: Ano 1 | R4: Ano 1 | S4: Ano 1 | T4: Ano 1 | U4: Ano 1 | V4: Ano 1 | W4: Ano 1 | X4: Ano 1 | Y4: Ano 1 | Z4: Ano 1 | AA4: Ano 2 | AB4: Ano 2 | AC4: Ano 2 | AD4: Ano 2 | AE4: Ano 2 | AF4: Ano 2 | AG4: Ano 2 | AH4: Ano 2 | AI4: Ano 2 | AJ4: Ano 2 | AK4: Ano 2 | AL4: Ano 2 | AM4: Ano 3 | AN4: Ano 3 | AO4: Ano 3 | AP4: Ano 3 | AQ4: Ano 3 | AR4: Ano 3 | AS4: Ano 3 | AT4: Ano 3 | AU4: Ano 3 | AV4: Ano 3 | AW4: Ano 3 | AX4: Ano 3 | AY4: Ano 4 | AZ4: Ano 4 | BA4: Ano 4 | BB4: Ano 4 | BC4: Ano 4 | BD4: Ano 4 | BE4: Ano 4 | BF4: Ano 4 | BG4: Ano 4 | BH4: Ano 4 | BI4: Ano 4 | BJ4: Ano 4 | BK4: Ano 5 | BL4: Ano 5 | BM4: Ano 5 | BN4: Ano 5 | BO4: Ano 5 | BP4: Ano 5 | BQ4: Ano 5 | BR4: Ano 5 | BS4: Ano 5 | BT4: Ano 5 | BU4: Ano 5 | BV4: Ano 5 | BW4: Ano 6 | BX4: Ano 6 | BY4: Ano 6 | BZ4: Ano 6 | CA4: Ano 6 | CB4: Ano 6 | CC4: Ano 6 | CD4: Ano 6 | CE4: Ano 6 | CF4: Ano 6 | CG4: Ano 6 | CH4: Ano 6 | CI4: Ano 7 | CJ4: Ano 7 | CK4: Ano 7 | CL4: Ano 7 | CM4: Ano 7 | CN4: Ano 7 | CO4: Ano 7 | CP4: Ano 7 | CQ4: Ano 7 | CR4: Ano 7 | CS4: Ano 7 | CT4: Ano 7 | CU4: Ano 8 | CV4: Ano 8 | CW4: Ano 8 | CX4: Ano 8 | CY4: Ano 8 | CZ4: Ano 8 | DA4: Ano 8 | DB4: Ano 8 | DC4: Ano 8 | DD4: Ano 8 | DE4: Ano 8 | DF4: Ano 8 | DG4: Ano 9 | DH4: Ano 9 | DI4: Ano 9 | DJ4: Ano 9 | DK4: Ano 9 | DL4: Ano 9 | DM4: Ano 9 | DN4: Ano 9 | DO4: Ano 9 | DP4: Ano 9 | DQ4: Ano 9 | DR4: Ano 9 | DS4: Ano 10 | DT4: Ano 10 | DU4: Ano 10 | DV4: Ano 10 | DW4: Ano 10 | DX4: Ano 10 | DY4: Ano 10 | DZ4: Ano 10 | EA4: Ano 10 | EB4: Ano 10 | EC4: Ano 10 | ED4: Ano 10
B7: Restaurantes | D7: =IF(AND(SUMIFS($O7:$BV7,$O$3:$BV$3,D$4)=0,D$11<>0),MAX(O7:BV7),SUMIFS($O7:$BV7,$O$3:$BV$3,D$4)) -> 25 | E7: =IF(AND(SUMIFS($O7:$BV7,$O$3:$BV$3,E$4)=0,E$11<>0),MAX(P7:EE7),SUMIFS($O7:$BV7,$O$3:$BV$3,E$4)) -> 25 | F7: =IF(AND(SUMIFS($O7:$BV7,$O$3:$BV$3,F$4)=0,F$11<>0),MAX(Q7:EF7),SUMIFS($O7:$BV7,$O$3:$BV$3,F$4)) -> 25 | G7: =IF(AND(SUMIFS($O7:$BV7,$O$3:$BV$3,G$4)=0,G$11<>0),MAX(R7:EG7),SUMIFS($O7:$BV7,$O$3:$BV$3,G$4)) -> 25 | H7: =IF(AND(SUMIFS($O7:$BV7,$O$3:$BV$3,H$4)=0,H$11<>0),MAX(S7:EH7),SUMIFS($O7:$BV7,$O$3:$BV$3,H$4)) -> 25 | I7: =IF(AND(SUMIFS($O7:$ED7,$O$3:$ED$3,I$4)=0,I$11<>0),MAX(T7:EI7),SUMIFS($O7:$ED7,$O$3:$ED$3,I$4)) -> 0 | J7: =IF(AND(SUMIFS($O7:$ED7,$O$3:$ED$3,J$4)=0,J$11<>0),MAX(U7:EJ7),SUMIFS($O7:$ED7,$O$3:$ED$3,J$4)) -> 0 | K7: =IF(AND(SUMIFS($O7:$ED7,$O$3:$ED$3,K$4)=0,K$11<>0),MAX(V7:EK7),SUMIFS($O7:$ED7,$O$3:$ED$3,K$4)) -> 0 | L7: =IF(AND(SUMIFS($O7:$ED7,$O$3:$ED$3,L$4)=0,L$11<>0),MAX(W7:EL7),SUMIFS($O7:$ED7,$O$3:$ED$3,L$4)) -> 0 | M7: =IF(AND(SUMIFS($O7:$ED7,$O$3:$ED$3,M$4)=0,M$11<>0),MAX(X7:EM7),SUMIFS($O7:$ED7,$O$3:$ED$3,M$4)) -> 0 | O7: =IF(Simulador!$E$10=Simulador!$E$12, IF(AND(O$2<=Simulador!$E$11,ROUNDUP(Simulador!$E$10/Simulador!$E$11*O$2,0)<=Simulador!$E$12), ROUNDUP(Simulador!$E$10/Simulador!$E$11*O$2,0), IF(O$2<=Simulador!$E$8,Simulador!$E$12,0) ), IF(O$2<=Simulador!$E$11, IF(ROUNDUP(Simulador!$E$10/Simulador!$E$11*O$2,0)<=Simulador!$E$12, ROUNDUP(Simulador!$E$10/Simulador!$E$11*O$2,0), 0 ), IF(ROUNDUP(Simulador!$E$10+(Simulador!$E$12-Simulador!$E$10)/(Simulador!$E$8-Simulador!$E$11)*(O$2-Simulador!$E$11),0)<=Simulador!$E$12, IF(O$2<=Simulador!$E$8, ROUNDUP(Simulador!$E$10+(Simulador!$E$12-Simulador!$E$10)/(Simulador!$E$8-Simulador!$E$11)*(O$2-Simulador!$E$11),0), 0 ), 0 ) ) ) -> 13 | P7: =IF(Simulador!$E$10=Simulador!$E$12, IF(AND(P$2<=Simulador!$E$11,ROUNDUP(Simulador!$E$10/Simulador!$E$11*P$2,0)<=Simulador!$E$12), ROUNDUP(Simulador!$E$10/Simulador!$E$11*P$2,0), IF(P$2<=Simulador!$E$8,Simulador!$E$12,0) ), IF(P$2<=Simulador!$E$11, IF(ROUNDUP(Simulador!$E$10/Simulador!$E$11*P$2,0)<=Simulador!$E$12, ROUNDUP(Simulador!$E$10/Simulador!$E$11*P$2,0), 0 ), IF(ROUNDUP(Simulador!$E$10+(Simulador!$E$12-Simulador!$E$10)/(Simulador!$E$8-Simulador!$E$11)*(P$2-Simulador!$E$11),0)<=Simulador!$E$12, IF(P$2<=Simulador!$E$8, ROUNDUP(Simulador!$E$10+(Simulador!$E$12-Simulador!$E$10)/(Simulador!$E$8-Simulador!$E$11)*(P$2-Simulador!$E$11),0), 0 ), 0 ) ) ) -> 25 | Q7: =IF(Simulador!$E$10=Simulador!$E$12, IF(AND(Q$2<=Simulador!$E$11,ROUNDUP(Simulador!$E$10/Simulador!$E$11*Q$2,0)<=Simulador!$E$12), ROUNDUP(Simulador!$E$10/Simulador!$E$11*Q$2,0), IF(Q$2<=Simulador!$E$8,Simulador!$E$12,0) ), IF(Q$2<=Simulador!$E$11, IF(ROUNDUP(Simulador!$E$10/Simulador!$E$11*Q$2,0)<=Simulador!$E$12, ROUNDUP(Simulador!$E$10/Simulador!$E$11*Q$2,0), 0 ), IF(ROUNDUP(Simulador!$E$10+(Simulador!$E$12-Simulador!$E$10)/(Simulador!$E$8-Simulador!$E$11)*(Q$2-Simulador!$E$11),0)<=Simulador!$E$12, IF(Q$2<=Simulador!$E$8, ROUNDUP(Simulador!$E$10+(Simulador!$E$12-Simulador!$E$10)/(Simulador!$E$8-Simulador!$E$11)*(Q$2-Simulador!$E$11),0), 0 ), 0 ) ) ) -> 25 | R7: =IF(Simulador!$E$10=Simulador!$E$12, IF(AND(R$2<=Simulador!$E$11,ROUNDUP(Simulador!$E$10/Simulador!$E$11*R$2,0)<=Simulador!$E$12), ROUNDUP(Simulador!$E$10/Simulador!$E$11*R$2,0), IF(R$2<=Simulador!$E$8,Simulador!$E$12,0) ), IF(R$2<=Simulador!$E$11, IF(ROUNDUP(Simulador!$E$10/Simulador!$E$11*R$2,0)<=Simulador!$E$12, ROUNDUP(Simulador!$E$10/Simulador!$E$11*R$2,0), 0 ), IF(ROUNDUP(Simulador!$E$10+(Simulador!$E$12-Simulador!$E$10)/(Simulador!$E$8-Simulador!$E$11)*(R$2-Simulador!$E$11),0)<=Simulador!$E$12, IF(R$2<=Simulador!$E$8, ROUNDUP(Simulador!$E$10+(Simulador!$E$12-Simulador!$E$10)/(Simulador!$E$8-Simulador!$E$11)*(R$2-Simulador!$E$11),0), 0 ), 0 ) ) ) -> 25 | S7: =IF(Simulador!$E$10=Simulador!$E$12, IF(AND(S$2<=Simulador!$E$11,ROUNDUP(Simulador!$E$10/Simulador!$E$11*S$2,0)<=Simulador!$E$12), ROUNDUP(Simulador!$E$10/Simulador!$E$11*S$2,0), IF(S$2<=Simulador!$E$8,Simulador!$E$12,0) ), IF(S$2<=Simulador!$E$11, IF(ROUNDUP(Simulador!$E$10/Simulador!$E$11*S$2,0)<=Simulador!$E$12, ROUNDUP(Simulador!$E$10/Simulador!$E$11*S$2,0), 0 ), IF(ROUNDUP(Simulador!$E$10+(Simulador!$E$12-Simulador!$E$10)/(Simulador!$E$8-Simulador!$E$11)*(S$2-Simulador!$E$11),0)<=Simulador!$E$12, IF(S$2<=Simulador!$E$8, ROUNDUP(Simulador!$E$10+(Simulador!$E$12-Simulador!$E$10)/(Simulador!$E$8-Simulador!$E$11)*(S$2-Simulador!$E$11),0), 0 ), 0 ) ) ) -> 25 | T7: =IF(Simulador!$E$10=Simulador!$E$12, IF(AND(T$2<=Simulador!$E$11,ROUNDUP(Simulador!$E$10/Simulador!$E$11*T$2,0)<=Simulador!$E$12), ROUNDUP(Simulador!$E$10/Simulador!$E$11*T$2,0), IF(T$2<=Simulador!$E$8,Simulador!$E$12,0) ), IF(T$2<=Simulador!$E$11, IF(ROUNDUP(Simulador!$E$10/Simulador!$E$11*T$2,0)<=Simulador!$E$12, ROUNDUP(Simulador!$E$10/Simulador!$E$11*T$2,0), 0 ), IF(ROUNDUP(Simulador!$E$10+(Simulador!$E$12-Simulador!$E$10)/(Simulador!$E$8-Simulador!$E$11)*(T$2-Simulador!$E$11),0)<=Simulador!$E$12, IF(T$2<=Simulador!$E$8, ROUNDUP(Simulador!$E$10+(Simulador!$E$12-Simulador!$E$10)/(Simulador!$E$8-Simulador!$E$11)*(T$2-Simulador!$E$11),0), 0 ), 0 ) ) ) -> 25 | U7: =IF(Simulador!$E$10=Simulador!$E$12, IF(AND(U$2<=Simulador!$E$11,ROUNDUP(Simulador!$E$10/Simulador!$E$11*U$2,0)<=Simulador!$E$12), ROUNDUP(Simulador!$E$10/Simulador!$E$11*U$2,0), IF(U$2<=Simulador!$E$8,Simulador!$E$12,0) ), IF(U$2<=Simulador!$E$11, IF(ROUNDUP(Simulador!$E$10/Simulador!$E$11*U$2,0)<=Simulador!$E$12, ROUNDUP(Simulador!$E$10/Simulador!$E$11*U$2,0), 0 ), IF(ROUNDUP(Simulador!$E$10+(Simulador!$E$12-Simulador!$E$10)/(Simulador!$E$8-Simulador!$E$11)*(U$2-Simulador!$E$11),0)<=Simulador!$E$12, IF(U$2<=Simulador!$E$8, ROUNDUP(Simulador!$E$10+(Simulador!$E$12-Simulador!$E$10)/(Simulador!$E$8-Simulador!$E$11)*(U$2-Simulador!$E$11),0), 0 ), 0 ) ) ) -> 25 | V7: =IF(Simulador!$E$10=Simulador!$E$12, IF(AND(V$2<=Simulador!$E$11,ROUNDUP(Simulador!$E$10/Simulador!$E$11*V$2,0)<=Simulador!$E$12), ROUNDUP(Simulador!$E$10/Simulador!$E$11*V$2,0), IF(V$2<=Simulador!$E$8,Simulador!$E$12,0) ), IF(V$2<=Simulador!$E$11, IF(ROUNDUP(Simulador!$E$10/Simulador!$E$11*V$2,0)<=Simulador!$E$12, ROUNDUP(Simulador!$E$10/Simulador!$E$11*V$2,0), 0 ), IF(ROUNDUP(Simulador!$E$10+(Simulador!$E$12-Simulador!$E$10)/(Simulador!$E$8-Simulador!$E$11)*(V$2-Simulador!$E$11),0)<=Simulador!$E$12, IF(V$2<=Simulador!$E$8, ROUNDUP(Simulador!$E$10+(Simulador!$E$12-Simulador!$E$10)/(Simulador!$E$8-Simulador!$E$11)*(V$2-Simulador!$E$11),0), 0 ), 0 ) ) ) -> 25 | ... ED7: =IF(Simulador!$E$10=Simulador!$E$12, IF(AND(ED$2<=Simulador!$E$11,ROUNDUP(Simulador!$E$10/Simulador!$E$11*ED$2,0)<=Simulador!$E$12), ROUNDUP(Simulador!$E$10/Simulador!$E$11*ED$2,0), IF(ED$2<=Simulador!$E$8,Simulador!$E$12,0) ), IF(ED$2<=Simulador!$E$11, IF(ROUNDUP(Simulador!$E$10/Simulador!$E$11*ED$2,0)<=Simulador!$E$12, ROUNDUP(Simulador!$E$10/Simulador!$E$11*ED$2,0), 0 ), IF(ROUNDUP(Simulador!$E$10+(Simulador!$E$12-Simulador!$E$10)/(Simulador!$E$8-Simulador!$E$11)*(ED$2-Simulador!$E$11),0)<=Simulador!$E$12, IF(ED$2<=Simulador!$E$8, ROUNDUP(Simulador!$E$10+(Simulador!$E$12-Simulador!$E$10)/(Simulador!$E$8-Simulador!$E$11)*(ED$2-Simulador!$E$11),0), 0 ), 0 ) ) ) -> 0
B9: PDV | D9: =IF(AND(SUMIFS($O9:$BV9,$O$3:$BV$3,D$4)=0,D$11<>0),MAX(O9:BV9),SUMIFS($O9:$BV9,$O$3:$BV$3,D$4)) -> 25 | E9: =IF(AND(SUMIFS($O9:$BV9,$O$3:$BV$3,E$4)=0,E$11<>0),MAX(P9:EE9),SUMIFS($O9:$BV9,$O$3:$BV$3,E$4)) -> 25 | F9: =IF(AND(SUMIFS($O9:$BV9,$O$3:$BV$3,F$4)=0,F$11<>0),MAX(Q9:EF9),SUMIFS($O9:$BV9,$O$3:$BV$3,F$4)) -> 25 | G9: =IF(AND(SUMIFS($O9:$BV9,$O$3:$BV$3,G$4)=0,G$11<>0),MAX(R9:EG9),SUMIFS($O9:$BV9,$O$3:$BV$3,G$4)) -> 25 | H9: =IF(AND(SUMIFS($O9:$BV9,$O$3:$BV$3,H$4)=0,H$11<>0),MAX(S9:EH9),SUMIFS($O9:$BV9,$O$3:$BV$3,H$4)) -> 25 | I9: =IF(AND(SUMIFS($O9:$ED9,$O$3:$ED$3,I$4)=0,I$11<>0),MAX(T9:EI9),SUMIFS($O9:$ED9,$O$3:$ED$3,I$4)) -> 0 | J9: =IF(AND(SUMIFS($O9:$ED9,$O$3:$ED$3,J$4)=0,J$11<>0),MAX(U9:EJ9),SUMIFS($O9:$ED9,$O$3:$ED$3,J$4)) -> 0 | K9: =IF(AND(SUMIFS($O9:$ED9,$O$3:$ED$3,K$4)=0,K$11<>0),MAX(V9:EK9),SUMIFS($O9:$ED9,$O$3:$ED$3,K$4)) -> 0 | L9: =IF(AND(SUMIFS($O9:$ED9,$O$3:$ED$3,L$4)=0,L$11<>0),MAX(W9:EL9),SUMIFS($O9:$ED9,$O$3:$ED$3,L$4)) -> 0 | M9: =IF(AND(SUMIFS($O9:$ED9,$O$3:$ED$3,M$4)=0,M$11<>0),MAX(X9:EM9),SUMIFS($O9:$ED9,$O$3:$ED$3,M$4)) -> 0 | O9: =O7*Simulador!$E$22 -> 13 | P9: =P7*Simulador!$E$22 -> 25 | Q9: =Q7*Simulador!$E$22 -> 25 | R9: =R7*Simulador!$E$22 -> 25 | S9: =S7*Simulador!$E$22 -> 25 | T9: =T7*Simulador!$E$22 -> 25 | U9: =U7*Simulador!$E$22 -> 25 | V9: =V7*Simulador!$E$22 -> 25 | ... ED9: =ED7*Simulador!$E$22 -> 0
B11: Pedidos | D11: =SUMIFS($O11:$BV11,$O$4:$BV$4,D$3) -> 0 | E11: =SUMIFS($O11:$BV11,$O$4:$BV$4,E$3) -> 0 | F11: =SUMIFS($O11:$BV11,$O$4:$BV$4,F$3) -> 0 | G11: =SUMIFS($O11:$BV11,$O$4:$BV$4,G$3) -> 0 | H11: =SUMIFS($O11:$BV11,$O$4:$BV$4,H$3) -> 0 | I11: =SUMIFS($O11:$ED11,$O$4:$ED$4,I$3) -> 0 | J11: =SUMIFS($O11:$ED11,$O$4:$ED$4,J$3) -> 0 | K11: =SUMIFS($O11:$ED11,$O$4:$ED$4,K$3) -> 0 | L11: =SUMIFS($O11:$ED11,$O$4:$ED$4,L$3) -> 0 | M11: =SUMIFS($O11:$ED11,$O$4:$ED$4,M$3) -> 0 | O11: =O7*Simulador!$E$14 -> 0 | P11: =P7*Simulador!$E$14 -> 0 | Q11: =Q7*Simulador!$E$14 -> 0 | R11: =R7*Simulador!$E$14 -> 0 | S11: =S7*Simulador!$E$14 -> 0 | T11: =T7*Simulador!$E$14 -> 0 | U11: =U7*Simulador!$E$14 -> 0 | V11: =V7*Simulador!$E$14 -> 0 | ... ED11: =ED7*Simulador!$E$14 -> 0
B13: GMV | D13: =SUMIFS($O13:$BV13,$O$4:$BV$4,D$3) -> 0 | E13: =SUMIFS($O13:$BV13,$O$4:$BV$4,E$3) -> 0 | F13: =SUMIFS($O13:$BV13,$O$4:$BV$4,F$3) -> 0 | G13: =SUMIFS($O13:$BV13,$O$4:$BV$4,G$3) -> 0 | H13: =SUMIFS($O13:$BV13,$O$4:$BV$4,H$3) -> 0 | I13: =SUMIFS($O13:$ED13,$O$4:$ED$4,I$3) -> 0 | J13: =SUMIFS($O13:$ED13,$O$4:$ED$4,J$3) -> 0 | K13: =SUMIFS($O13:$ED13,$O$4:$ED$4,K$3) -> 0 | L13: =SUMIFS($O13:$ED13,$O$4:$ED$4,L$3) -> 0 | M13: =SUMIFS($O13:$ED13,$O$4:$ED$4,M$3) -> 0 | O13: =O11*Simulador!$E$16 -> 0 | P13: =P11*Simulador!$E$16 -> 0 | Q13: =Q11*Simulador!$E$16 -> 0 | R13: =R11*Simulador!$E$16 -> 0 | S13: =S11*Simulador!$E$16 -> 0 | T13: =T11*Simulador!$E$16 -> 0 | U13: =U11*Simulador!$E$16 -> 0 | V13: =V11*Simulador!$E$16 -> 0 | ... ED13: =ED11*Simulador!$E$16 -> 0
B15: TPV | D15: =SUMIFS($O15:$BV15,$O$4:$BV$4,D$3) -> 0 | E15: =SUMIFS($O15:$BV15,$O$4:$BV$4,E$3) -> 0 | F15: =SUMIFS($O15:$BV15,$O$4:$BV$4,F$3) -> 0 | G15: =SUMIFS($O15:$BV15,$O$4:$BV$4,G$3) -> 0 | H15: =SUMIFS($O15:$BV15,$O$4:$BV$4,H$3) -> 0 | I15: =SUMIFS($O15:$ED15,$O$4:$ED$4,I$3) -> 0 | J15: =SUMIFS($O15:$ED15,$O$4:$ED$4,J$3) -> 0 | K15: =SUMIFS($O15:$ED15,$O$4:$ED$4,K$3) -> 0 | L15: =SUMIFS($O15:$ED15,$O$4:$ED$4,L$3) -> 0 | M15: =SUMIFS($O15:$ED15,$O$4:$ED$4,M$3) -> 0 | O15: =IF(Simulador!$E$18=TRUE,O13,0) -> 0 | P15: =IF(Simulador!$E$18=TRUE,P13,0) -> 0 | Q15: =IF(Simulador!$E$18=TRUE,Q13,0) -> 0 | R15: =IF(Simulador!$E$18=TRUE,R13,0) -> 0 | S15: =IF(Simulador!$E$18=TRUE,S13,0) -> 0 | T15: =IF(Simulador!$E$18=TRUE,T13,0) -> 0 | U15: =IF(Simulador!$E$18=TRUE,U13,0) -> 0 | V15: =IF(Simulador!$E$18=TRUE,V13,0) -> 0 | ... ED15: =IF(Simulador!$E$18=TRUE,ED13,0) -> 0
B18: Receita Total | D18: =SUM(D19:D23) -> 208550 | E18: =SUM(E19:E23) -> 180000 | F18: =SUM(F19:F23) -> 180000 | G18: =SUM(G19:G23) -> 180000 | H18: =SUM(H19:H23) -> 180000 | I18: =SUM(I19:I23) -> 0 | J18: =SUM(J19:J23) -> 0 | K18: =SUM(K19:K23) -> 0 | ... M18: =SUM(M19:M23) -> 0 | O18: =SUM(O19:O23) -> 24086 | P18: =SUM(P19:P23) -> 34464 | Q18: =SUM(Q19:Q23) -> 15000 | R18: =SUM(R19:R23) -> 15000 | S18: =SUM(S19:S23) -> 15000 | T18: =SUM(T19:T23) -> 15000 | U18: =SUM(U19:U23) -> 15000 | V18: =SUM(V19:V23) -> 15000 | ... ED18: =SUM(ED19:ED23) -> 0
B19: Receita PDV | D19: =SUMIFS($O19:$BV19,$O$4:$BV$4,D$3) -> 165000 | E19: =SUMIFS($O19:$BV19,$O$4:$BV$4,E$3) -> 180000 | F19: =SUMIFS($O19:$BV19,$O$4:$BV$4,F$3) -> 180000 | G19: =SUMIFS($O19:$BV19,$O$4:$BV$4,G$3) -> 180000 | H19: =SUMIFS($O19:$BV19,$O$4:$BV$4,H$3) -> 180000 | I19: =SUMIFS($O19:$ED19,$O$4:$ED$4,I$3) -> 0 | J19: =SUMIFS($O19:$ED19,$O$4:$ED$4,J$3) -> 0 | K19: =SUMIFS($O19:$ED19,$O$4:$ED$4,K$3) -> 0 | L19: =SUMIFS($O19:$ED19,$O$4:$ED$4,L$3) -> 0 | M19: =SUMIFS($O19:$ED19,$O$4:$ED$4,M$3) -> 0 | O19: =IF(O$1<=Simulador!$E$37,0,O9*Simulador!$E$23) -> 0 | P19: =IF(P$1<=Simulador!$E$37,0,P9*Simulador!$E$23) -> 15000 | Q19: =IF(Q$1<=Simulador!$E$37,0,Q9*Simulador!$E$23) -> 15000 | R19: =IF(R$1<=Simulador!$E$37,0,R9*Simulador!$E$23) -> 15000 | S19: =IF(S$1<=Simulador!$E$37,0,S9*Simulador!$E$23) -> 15000 | T19: =IF(T$1<=Simulador!$E$37,0,T9*Simulador!$E$23) -> 15000 | U19: =IF(U$1<=Simulador!$E$37,0,U9*Simulador!$E$23) -> 15000 | V19: =IF(V$1<=Simulador!$E$37,0,V9*Simulador!$E$23) -> 15000 | ... ED19: =IF(ED$1<=Simulador!$E$37,0,ED9*Simulador!$E$23) -> 0
B20: Serviços adicionais | D20: =IF(AND(SUMIFS($O20:$BV20,$O$3:$BV$3,D$4)=0,D$11<>0),MAX(O20:BV20),SUMIFS($O20:$BV20,$O$3:$BV$3,D$4)) -> 0 | E20: =IF(AND(SUMIFS($O20:$BV20,$O$3:$BV$3,E$4)=0,E$11<>0),MAX(P20:EE20),SUMIFS($O20:$BV20,$O$3:$BV$3,E$4)) -> 0 | F20: =IF(AND(SUMIFS($O20:$BV20,$O$3:$BV$3,F$4)=0,F$11<>0),MAX(Q20:EF20),SUMIFS($O20:$BV20,$O$3:$BV$3,F$4)) -> 0 | G20: =IF(AND(SUMIFS($O20:$BV20,$O$3:$BV$3,G$4)=0,G$11<>0),MAX(R20:EG20),SUMIFS($O20:$BV20,$O$3:$BV$3,G$4)) -> 0 | H20: =IF(AND(SUMIFS($O20:$BV20,$O$3:$BV$3,H$4)=0,H$11<>0),MAX(S20:EH20),SUMIFS($O20:$BV20,$O$3:$BV$3,H$4)) -> 0 | I20: =IF(AND(SUMIFS($O20:$ED20,$O$3:$ED$3,I$4)=0,I$11<>0),MAX(T20:EI20),SUMIFS($O20:$ED20,$O$3:$ED$3,I$4)) -> 0 | J20: =IF(AND(SUMIFS($O20:$ED20,$O$3:$ED$3,J$4)=0,J$11<>0),MAX(U20:EJ20),SUMIFS($O20:$ED20,$O$3:$ED$3,J$4)) -> 0 | K20: =IF(AND(SUMIFS($O20:$ED20,$O$3:$ED$3,K$4)=0,K$11<>0),MAX(V20:EK20),SUMIFS($O20:$ED20,$O$3:$ED$3,K$4)) -> 0 | L20: =IF(AND(SUMIFS($O20:$ED20,$O$3:$ED$3,L$4)=0,L$11<>0),MAX(W20:EL20),SUMIFS($O20:$ED20,$O$3:$ED$3,L$4)) -> 0 | M20: =IF(AND(SUMIFS($O20:$ED20,$O$3:$ED$3,M$4)=0,M$11<>0),MAX(X20:EM20),SUMIFS($O20:$ED20,$O$3:$ED$3,M$4)) -> 0 | O20: =O$7*Simulador!$E$26 -> 0 | P20: =P$7*Simulador!$E$26 -> 0 | Q20: =Q$7*Simulador!$E$26 -> 0 | R20: =R$7*Simulador!$E$26 -> 0 | S20: =S$7*Simulador!$E$26 -> 0 | T20: =T$7*Simulador!$E$26 -> 0 | U20: =U$7*Simulador!$E$26 -> 0 | V20: =V$7*Simulador!$E$26 -> 0 | ... ED20: =ED$7*Simulador!$E$26 -> 0
B21: Receita Payments | D21: =SUMIFS($O21:$BV21,$O$4:$BV$4,D$3) -> 0 | E21: =SUMIFS($O21:$BV21,$O$4:$BV$4,E$3) -> 0 | F21: =SUMIFS($O21:$BV21,$O$4:$BV$4,F$3) -> 0 | G21: =SUMIFS($O21:$BV21,$O$4:$BV$4,G$3) -> 0 | H21: =SUMIFS($O21:$BV21,$O$4:$BV$4,H$3) -> 0 | I21: =SUMIFS($O21:$ED21,$O$4:$ED$4,I$3) -> 0 | J21: =SUMIFS($O21:$ED21,$O$4:$ED$4,J$3) -> 0 | K21: =SUMIFS($O21:$ED21,$O$4:$ED$4,K$3) -> 0 | L21: =SUMIFS($O21:$ED21,$O$4:$ED$4,L$3) -> 0 | M21: =SUMIFS($O21:$ED21,$O$4:$ED$4,M$3) -> 0 | O21: 0 | P21: =P$15*Premissas!$C$3 -> 0 | Q21: =Q$15*Premissas!$C$3 -> 0 | R21: =R$15*Premissas!$C$3 -> 0 | S21: =S$15*Premissas!$C$3 -> 0 | T21: =T$15*Premissas!$C$3 -> 0 | U21: =U$15*Premissas!$C$3 -> 0 | V21: =V$15*Premissas!$C$3 -> 0 | W21: =W$15*Premissas!$C$3 -> 0 | ... ED21: =ED$15*Premissas!$C$3 -> 0
B22: Receita Implantação | D22: =SUMIFS($O22:$BV22,$O$4:$BV$4,D$3) -> 40550 | E22: =SUMIFS($O22:$BV22,$O$4:$BV$4,E$3) -> 0 | F22: =SUMIFS($O22:$BV22,$O$4:$BV$4,F$3) -> 0 | G22: =SUMIFS($O22:$BV22,$O$4:$BV$4,G$3) -> 0 | H22: =SUMIFS($O22:$BV22,$O$4:$BV$4,H$3) -> 0 | I22: =SUMIFS($O22:$ED22,$O$4:$ED$4,I$3) -> 0 | J22: =SUMIFS($O22:$ED22,$O$4:$ED$4,J$3) -> 0 | K22: =SUMIFS($O22:$ED22,$O$4:$ED$4,K$3) -> 0 | L22: =SUMIFS($O22:$ED22,$O$4:$ED$4,L$3) -> 0 | M22: =SUMIFS($O22:$ED22,$O$4:$ED$4,M$3) -> 0 | O22: =IF(IF(O7>Simulador!$E$10,Simulador!$E$28*(O7-N7),(Simulador!$E$28*(1-Simulador!$E$39)*(O7-N7)))<0,0,IF(O7>Simulador!$E$10,Simulador!$E$28*(O7-N7),(Simulador!$E$28*(1-Simulador!$E$39)*(O7-N7)))) -> 21086 | P22: =IF(IF(P7>Simulador!$E$10,Simulador!$E$28*(P7-O7),(Simulador!$E$28*(1-Simulador!$E$39)*(P7-O7)))<0,0,IF(P7>Simulador!$E$10,Simulador!$E$28*(P7-O7),(Simulador!$E$28*(1-Simulador!$E$39)*(P7-O7)))) -> 19464 | Q22: =IF(IF(Q7>Simulador!$E$10,Simulador!$E$28*(Q7-P7),(Simulador!$E$28*(1-Simulador!$E$39)*(Q7-P7)))<0,0,IF(Q7>Simulador!$E$10,Simulador!$E$28*(Q7-P7),(Simulador!$E$28*(1-Simulador!$E$39)*(Q7-P7)))) -> 0 | R22: =IF(IF(R7>Simulador!$E$10,Simulador!$E$28*(R7-Q7),(Simulador!$E$28*(1-Simulador!$E$39)*(R7-Q7)))<0,0,IF(R7>Simulador!$E$10,Simulador!$E$28*(R7-Q7),(Simulador!$E$28*(1-Simulador!$E$39)*(R7-Q7)))) -> 0 | S22: =IF(IF(S7>Simulador!$E$10,Simulador!$E$28*(S7-R7),(Simulador!$E$28*(1-Simulador!$E$39)*(S7-R7)))<0,0,IF(S7>Simulador!$E$10,Simulador!$E$28*(S7-R7),(Simulador!$E$28*(1-Simulador!$E$39)*(S7-R7)))) -> 0 | T22: =IF(IF(T7>Simulador!$E$10,Simulador!$E$28*(T7-S7),(Simulador!$E$28*(1-Simulador!$E$39)*(T7-S7)))<0,0,IF(T7>Simulador!$E$10,Simulador!$E$28*(T7-S7),(Simulador!$E$28*(1-Simulador!$E$39)*(T7-S7)))) -> 0 | U22: =IF(IF(U7>Simulador!$E$10,Simulador!$E$28*(U7-T7),(Simulador!$E$28*(1-Simulador!$E$39)*(U7-T7)))<0,0,IF(U7>Simulador!$E$10,Simulador!$E$28*(U7-T7),(Simulador!$E$28*(1-Simulador!$E$39)*(U7-T7)))) -> 0 | V22: =IF(IF(V7>Simulador!$E$10,Simulador!$E$28*(V7-U7),(Simulador!$E$28*(1-Simulador!$E$39)*(V7-U7)))<0,0,IF(V7>Simulador!$E$10,Simulador!$E$28*(V7-U7),(Simulador!$E$28*(1-Simulador!$E$39)*(V7-U7)))) -> 0 | ... ED22: =IF(IF(ED7>Simulador!$E$10,Simulador!$E$28*(ED7-EC7),(Simulador!$E$28*(1-Simulador!$E$39)*(ED7-EC7)))<0,0,IF(ED7>Simulador!$E$10,Simulador!$E$28*(ED7-EC7),(Simulador!$E$28*(1-Simulador!$E$39)*(ED7-EC7)))) -> 0
B23: Setup | D23: =SUMIFS($O23:$BV23,$O$4:$BV$4,D$3) -> 3000 | E23: =SUMIFS($O23:$BV23,$O$4:$BV$4,E$3) -> 0 | F23: =SUMIFS($O23:$BV23,$O$4:$BV$4,F$3) -> 0 | G23: =SUMIFS($O23:$BV23,$O$4:$BV$4,G$3) -> 0 | H23: =SUMIFS($O23:$BV23,$O$4:$BV$4,H$3) -> 0 | I23: =SUMIFS($O23:$ED23,$O$4:$ED$4,I$3) -> 0 | J23: =SUMIFS($O23:$ED23,$O$4:$ED$4,J$3) -> 0 | K23: =SUMIFS($O23:$ED23,$O$4:$ED$4,K$3) -> 0 | L23: =SUMIFS($O23:$ED23,$O$4:$ED$4,L$3) -> 0 | M23: =SUMIFS($O23:$ED23,$O$4:$ED$4,M$3) -> 0 | O23: =IF(Simulador!$E$41=TRUE,0,Simulador!$E$32) -> 3000 | P23: 0 | Q23: =P23 -> 0 | R23: =Q23 -> 0 | S23: =R23 -> 0 | T23: =S23 -> 0 | U23: =T23 -> 0 | V23: =U23 -> 0 | W23: =V23 -> 0 | X23: =W23 -> 0 | ... ED23: =EC23 -> 0
B24: Desconto | D24: =SUMIFS($O24:$BV24,$O$4:$BV$4,D$3) -> 0 | E24: =SUMIFS($O24:$BV24,$O$4:$BV$4,E$3) -> 0 | F24: =SUMIFS($O24:$BV24,$O$4:$BV$4,F$3) -> 0 | G24: =SUMIFS($O24:$BV24,$O$4:$BV$4,G$3) -> 0 | H24: =SUMIFS($O24:$BV24,$O$4:$BV$4,H$3) -> 0 | I24: =SUMIFS($O24:$ED24,$O$4:$ED$4,I$3) -> 0 | J24: =SUMIFS($O24:$ED24,$O$4:$ED$4,J$3) -> 0 | K24: =SUMIFS($O24:$ED24,$O$4:$ED$4,K$3) -> 0 | L24: =SUMIFS($O24:$ED24,$O$4:$ED$4,L$3) -> 0 | M24: =SUMIFS($O24:$ED24,$O$4:$ED$4,M$3) -> 0 | O24: 0 | P24: =IF(P1<=Simulador!$E$45,Simulador!$E$44*-SUM(P19),0) -> 0 | Q24: =IF(Q1<=Simulador!$E$45,Simulador!$E$44*-SUM(Q19),0) -> 0 | R24: =IF(R1<=Simulador!$E$45,Simulador!$E$44*-SUM(R19),0) -> 0 | S24: =IF(S1<=Simulador!$E$45,Simulador!$E$44*-SUM(S19),0) -> 0 | T24: =IF(T1<=Simulador!$E$45,Simulador!$E$44*-SUM(T19),0) -> 0 | U24: =IF(U1<=Simulador!$E$45,Simulador!$E$44*-SUM(U19),0) -> 0 | V24: =IF(V1<=Simulador!$E$45,Simulador!$E$44*-SUM(V19),0) -> 0 | W24: =IF(W1<=Simulador!$E$45,Simulador!$E$44*-SUM(W19),0) -> 0 | ... ED24: =IF(ED1<=Simulador!$E$45,Simulador!$E$44*-SUM(ED19),0) -> 0
B26: Receita com desconto | D26: =SUMIFS($O26:$BV26,$O$4:$BV$4,D$3) -> 208550 | E26: =SUMIFS($O26:$BV26,$O$4:$BV$4,E$3) -> 180000 | F26: =SUMIFS($O26:$BV26,$O$4:$BV$4,F$3) -> 180000 | G26: =SUMIFS($O26:$BV26,$O$4:$BV$4,G$3) -> 180000 | H26: =SUMIFS($O26:$BV26,$O$4:$BV$4,H$3) -> 180000 | I26: =SUMIFS($O26:$ED26,$O$4:$ED$4,I$3) -> 0 | J26: =SUMIFS($O26:$ED26,$O$4:$ED$4,J$3) -> 0 | K26: =SUMIFS($O26:$ED26,$O$4:$ED$4,K$3) -> 0 | L26: =SUMIFS($O26:$ED26,$O$4:$ED$4,L$3) -> 0 | M26: =SUMIFS($O26:$ED26,$O$4:$ED$4,M$3) -> 0 | O26: =IF(ABS(O24)<O18,O18+O24,0) -> 24086 | P26: =IF(ABS(P24)<P18,P18+P24,0) -> 34464 | Q26: =IF(ABS(Q24)<Q18,Q18+Q24,0) -> 15000 | R26: =IF(ABS(R24)<R18,R18+R24,0) -> 15000 | S26: =IF(ABS(S24)<S18,S18+S24,0) -> 15000 | T26: =IF(ABS(T24)<T18,T18+T24,0) -> 15000 | U26: =IF(ABS(U24)<U18,U18+U24,0) -> 15000 | V26: =IF(ABS(V24)<V18,V18+V24,0) -> 15000 | ... ED26: =IF(ABS(ED24)<ED18,ED18+ED24,0) -> 0
B27: Impostos | D27: =SUMIFS($O27:$BV27,$O$4:$BV$4,D$3) -> -14221.875 | E27: =SUMIFS($O27:$BV27,$O$4:$BV$4,E$3) -> -10170 | F27: =SUMIFS($O27:$BV27,$O$4:$BV$4,F$3) -> -10170 | G27: =SUMIFS($O27:$BV27,$O$4:$BV$4,G$3) -> -10170 | H27: =SUMIFS($O27:$BV27,$O$4:$BV$4,H$3) -> -10170 | I27: =SUMIFS($O27:$ED27,$O$4:$ED$4,I$3) -> 0 | J27: =SUMIFS($O27:$ED27,$O$4:$ED$4,J$3) -> 0 | K27: =SUMIFS($O27:$ED27,$O$4:$ED$4,K$3) -> 0 | L27: =SUMIFS($O27:$ED27,$O$4:$ED$4,L$3) -> 0 | M27: =SUMIFS($O27:$ED27,$O$4:$ED$4,M$3) -> 0 | O27: =(SUM(O19,O24)*-5.65%)+(SUM(O21,O22,O20,O23)*-11.25%) -> -2709.675 | P27: =(SUM(P19,P24)*-5.65%)+(SUM(P21,P22,P20,P23)*-11.25%) -> -3037.2 | Q27: =(SUM(Q19,Q24)*-5.65%)+(SUM(Q21,Q22,Q20,Q23)*-11.25%) -> -847.5 | R27: =(SUM(R19,R24)*-5.65%)+(SUM(R21,R22,R20,R23)*-11.25%) -> -847.5 | S27: =(SUM(S19,S24)*-5.65%)+(SUM(S21,S22,S20,S23)*-11.25%) -> -847.5 | T27: =(SUM(T19,T24)*-5.65%)+(SUM(T21,T22,T20,T23)*-11.25%) -> -847.5 | U27: =(SUM(U19,U24)*-5.65%)+(SUM(U21,U22,U20,U23)*-11.25%) -> -847.5 | V27: =(SUM(V19,V24)*-5.65%)+(SUM(V21,V22,V20,V23)*-11.25%) -> -847.5 | ... ED27: =(SUM(ED19,ED24)*-5.65%)+(SUM(ED21,ED22,ED20,ED23)*-11.25%) -> 0
B29: Receita Líquida | D29: =SUMIFS($O29:$BV29,$O$4:$BV$4,D$3) -> 194328.12 | E29: =SUMIFS($O29:$BV29,$O$4:$BV$4,E$3) -> 169830 | F29: =SUMIFS($O29:$BV29,$O$4:$BV$4,F$3) -> 169830 | G29: =SUMIFS($O29:$BV29,$O$4:$BV$4,G$3) -> 169830 | H29: =SUMIFS($O29:$BV29,$O$4:$BV$4,H$3) -> 169830 | I29: =SUMIFS($O29:$ED29,$O$4:$ED$4,I$3) -> 0 | J29: =SUMIFS($O29:$ED29,$O$4:$ED$4,J$3) -> 0 | K29: =SUMIFS($O29:$ED29,$O$4:$ED$4,K$3) -> 0 | L29: =SUMIFS($O29:$ED29,$O$4:$ED$4,L$3) -> 0 | M29: =SUMIFS($O29:$ED29,$O$4:$ED$4,M$3) -> 0 | O29: =O26+O27 -> 21376.325 | P29: =P26+P27 -> 31426.8 | Q29: =Q26+Q27 -> 14152.5 | R29: =R26+R27 -> 14152.5 | S29: =S26+S27 -> 14152.5 | T29: =T26+T27 -> 14152.5 | U29: =U26+U27 -> 14152.5 | V29: =V26+V27 -> 14152.5 | ... ED29: =ED26+ED27 -> 0
B31: Custos Operacionais | D31: =SUM(D32:D36) -> -94682.75 | E31: =SUM(E32:E36) -> -39650 | F31: =SUM(F32:F36) -> -39650 | G31: =SUM(G32:G36) -> -39650 | H31: =SUM(H32:H36) -> -39650 | I31: =SUM(I32:I36) -> 0 | J31: =SUM(J32:J36) -> 0 | K31: =SUM(K32:K36) -> 0 | ... M31: =SUM(M32:M36) -> 0 | O31: =SUM(O32:O36) -> -31159.917 | P31: =SUM(P32:P36) -> -30481.167 | Q31: =SUM(Q32:Q36) -> -3304.1667 | R31: =SUM(R32:R36) -> -3304.1667 | S31: =SUM(S32:S36) -> -3304.1667 | T31: =SUM(T32:T36) -> -3304.1667 | U31: =SUM(U32:U36) -> -3304.1667 | V31: =SUM(V32:V36) -> -3304.1667 | ... ED31: =SUM(ED32:ED36) -> 0
B32: Custo Server&Tech | D32: =SUMIFS($O32:$BV32,$O$4:$BV$4,D$3) -> -17280 | E32: =SUMIFS($O32:$BV32,$O$4:$BV$4,E$3) -> -18000 | F32: =SUMIFS($O32:$BV32,$O$4:$BV$4,F$3) -> -18000 | G32: =SUMIFS($O32:$BV32,$O$4:$BV$4,G$3) -> -18000 | H32: =SUMIFS($O32:$BV32,$O$4:$BV$4,H$3) -> -18000 | I32: =SUMIFS($O32:$ED32,$O$4:$ED$4,I$3) -> 0 | J32: =SUMIFS($O32:$ED32,$O$4:$ED$4,J$3) -> 0 | K32: =SUMIFS($O32:$ED32,$O$4:$ED$4,K$3) -> 0 | L32: =SUMIFS($O32:$ED32,$O$4:$ED$4,L$3) -> 0 | M32: =SUMIFS($O32:$ED32,$O$4:$ED$4,M$3) -> 0 | O32: =O9*Premissas!$C$5 -> -780 | P32: =P9*Premissas!$C$5 -> -1500 | Q32: =Q9*Premissas!$C$5 -> -1500 | R32: =R9*Premissas!$C$5 -> -1500 | S32: =S9*Premissas!$C$5 -> -1500 | T32: =T9*Premissas!$C$5 -> -1500 | U32: =U9*Premissas!$C$5 -> -1500 | V32: =V9*Premissas!$C$5 -> -1500 | ... ED32: =ED9*Premissas!$C$5 -> 0
B33: Custo Supporting | D33: =SUMIFS($O33:$BV33,$O$4:$BV$4,D$3) -> -20784 | E33: =SUMIFS($O33:$BV33,$O$4:$BV$4,E$3) -> -21650 | F33: =SUMIFS($O33:$BV33,$O$4:$BV$4,F$3) -> -21650 | G33: =SUMIFS($O33:$BV33,$O$4:$BV$4,G$3) -> -21650 | H33: =SUMIFS($O33:$BV33,$O$4:$BV$4,H$3) -> -21650 | I33: =SUMIFS($O33:$ED33,$O$4:$ED$4,I$3) -> 0 | J33: =SUMIFS($O33:$ED33,$O$4:$ED$4,J$3) -> 0 | K33: =SUMIFS($O33:$ED33,$O$4:$ED$4,K$3) -> 0 | L33: =SUMIFS($O33:$ED33,$O$4:$ED$4,L$3) -> 0 | M33: =SUMIFS($O33:$ED33,$O$4:$ED$4,M$3) -> 0 | O33: =O9*Premissas!$C$7 -> -938.16667 | P33: =P9*Premissas!$C$7 -> -1804.1667 | Q33: =Q9*Premissas!$C$7 -> -1804.1667 | R33: =R9*Premissas!$C$7 -> -1804.1667 | S33: =S9*Premissas!$C$7 -> -1804.1667 | T33: =T9*Premissas!$C$7 -> -1804.1667 | U33: =U9*Premissas!$C$7 -> -1804.1667 | V33: =V9*Premissas!$C$7 -> -1804.1667 | ... ED33: =ED9*Premissas!$C$7 -> 0
B34: Custo Suporte Dedicado | D34: =SUMIFS($O34:$BV34,$O$4:$BV$4,D$3) -> 0 | E34: =SUMIFS($O34:$BV34,$O$4:$BV$4,E$3) -> 0 | F34: =SUMIFS($O34:$BV34,$O$4:$BV$4,F$3) -> 0 | G34: =SUMIFS($O34:$BV34,$O$4:$BV$4,G$3) -> 0 | H34: =SUMIFS($O34:$BV34,$O$4:$BV$4,H$3) -> 0 | I34: =SUMIFS($O34:$ED34,$O$4:$ED$4,I$3) -> 0 | J34: =SUMIFS($O34:$ED34,$O$4:$ED$4,J$3) -> 0 | K34: =SUMIFS($O34:$ED34,$O$4:$ED$4,K$3) -> 0 | L34: =SUMIFS($O34:$ED34,$O$4:$ED$4,L$3) -> 0 | M34: =SUMIFS($O34:$ED34,$O$4:$ED$4,M$3) -> 0 | O34: =IF(O7>0,Simulador!$E$60*Premissas!$C$17,0) -> 0 | P34: =IF(P7>0,Simulador!$E$60*Premissas!$C$17,0) -> 0 | Q34: =IF(Q7>0,Simulador!$E$60*Premissas!$C$17,0) -> 0 | R34: =IF(R7>0,Simulador!$E$60*Premissas!$C$17,0) -> 0 | S34: =IF(S7>0,Simulador!$E$60*Premissas!$C$17,0) -> 0 | T34: =IF(T7>0,Simulador!$E$60*Premissas!$C$17,0) -> 0 | U34: =IF(U7>0,Simulador!$E$60*Premissas!$C$17,0) -> 0 | V34: =IF(V7>0,Simulador!$E$60*Premissas!$C$17,0) -> 0 | ... ED34: =IF(ED7>0,Simulador!$E$60*Premissas!$C$17,0) -> 0
B35: Custo Implantação | D35: =SUMIFS($O35:$BV35,$O$4:$BV$4,D$3) -> -56618.75 | E35: =SUMIFS($O35:$BV35,$O$4:$BV$4,E$3) -> 0 | F35: =SUMIFS($O35:$BV35,$O$4:$BV$4,F$3) -> 0 | G35: =SUMIFS($O35:$BV35,$O$4:$BV$4,G$3) -> 0 | H35: =SUMIFS($O35:$BV35,$O$4:$BV$4,H$3) -> 0 | I35: =SUMIFS($O35:$ED35,$O$4:$ED$4,I$3) -> 0 | J35: =SUMIFS($O35:$ED35,$O$4:$ED$4,J$3) -> 0 | K35: =SUMIFS($O35:$ED35,$O$4:$ED$4,K$3) -> 0 | L35: =SUMIFS($O35:$ED35,$O$4:$ED$4,L$3) -> 0 | M35: =SUMIFS($O35:$ED35,$O$4:$ED$4,M$3) -> 0 | O35: =Premissas!$C$9*MAX((O9-N9),0) -> -29441.75 | P35: =Premissas!$C$9*MAX((P9-O9),0) -> -27177 | Q35: =Premissas!$C$9*MAX((Q9-P9),0) -> 0 | R35: =Premissas!$C$9*MAX((R9-Q9),0) -> 0 | S35: =Premissas!$C$9*MAX((S9-R9),0) -> 0 | T35: =Premissas!$C$9*MAX((T9-S9),0) -> 0 | U35: =Premissas!$C$9*MAX((U9-T9),0) -> 0 | V35: =Premissas!$C$9*MAX((V9-U9),0) -> 0 | ... ED35: =Premissas!$C$9*MAX((ED9-EC9),0) -> 0
B36: Rebate | D36: =SUMIFS($O36:$BV36,$O$4:$BV$4,D$3) -> 0 | E36: =SUMIFS($O36:$BV36,$O$4:$BV$4,E$3) -> 0 | F36: =SUMIFS($O36:$BV36,$O$4:$BV$4,F$3) -> 0 | G36: =SUMIFS($O36:$BV36,$O$4:$BV$4,G$3) -> 0 | H36: =SUMIFS($O36:$BV36,$O$4:$BV$4,H$3) -> 0 | I36: =SUMIFS($O36:$ED36,$O$4:$ED$4,I$3) -> 0 | J36: =SUMIFS($O36:$ED36,$O$4:$ED$4,J$3) -> 0 | K36: =SUMIFS($O36:$ED36,$O$4:$ED$4,K$3) -> 0 | L36: =SUMIFS($O36:$ED36,$O$4:$ED$4,L$3) -> 0 | M36: =SUMIFS($O36:$ED36,$O$4:$ED$4,M$3) -> 0 | O36: =IF(O7=0,0,-Simulador!$E$64*SUM(O19:O21,O23)) -> 0 | P36: =IF(P7=0,0,-Simulador!$E$64*SUM(P19:P21,P23)) -> 0 | Q36: =IF(Q7=0,0,-Simulador!$E$64*SUM(Q19:Q21,Q23)) -> 0 | R36: =IF(R7=0,0,-Simulador!$E$64*SUM(R19:R21,R23)) -> 0 | S36: =IF(S7=0,0,-Simulador!$E$64*SUM(S19:S21,S23)) -> 0 | T36: =IF(T7=0,0,-Simulador!$E$64*SUM(T19:T21,T23)) -> 0 | U36: =IF(U7=0,0,-Simulador!$E$64*SUM(U19:U21,U23)) -> 0 | V36: =IF(V7=0,0,-Simulador!$E$64*SUM(V19:V21,V23)) -> 0 | ... ED36: =IF(ED7=0,0,-Simulador!$E$64*SUM(ED19:ED21,ED23)) -> 0
B38: CAC | D38: =SUMIFS($O38:$BV38,$O$4:$BV$4,D$3) -> -6085.1064 | E38: =SUMIFS($O38:$BV38,$O$4:$BV$4,E$3) -> 0 | F38: =SUMIFS($O38:$BV38,$O$4:$BV$4,F$3) -> 0 | G38: =SUMIFS($O38:$BV38,$O$4:$BV$4,G$3) -> 0 | H38: =SUMIFS($O38:$BV38,$O$4:$BV$4,H$3) -> 0 | I38: =SUMIFS($O38:$ED38,$O$4:$ED$4,I$3) -> 0 | J38: =SUMIFS($O38:$ED38,$O$4:$ED$4,J$3) -> 0 | K38: =SUMIFS($O38:$ED38,$O$4:$ED$4,K$3) -> 0 | L38: =SUMIFS($O38:$ED38,$O$4:$ED$4,L$3) -> 0 | M38: =SUMIFS($O38:$ED38,$O$4:$ED$4,M$3) -> 0 | O38: =SUM(O39:O44) -> -6085.1064 | P38: =SUM(P39:P44) -> 0 | Q38: =SUM(Q39:Q44) -> 0 | R38: =SUM(R39:R44) -> 0 | S38: =SUM(S39:S44) -> 0 | T38: =SUM(T39:T44) -> 0 | U38: =SUM(U39:U44) -> 0 | V38: =SUM(V39:V44) -> 0 | ... ED38: =SUM(ED39:ED44) -> 0
B39: Staff comercial | D39: =SUMIFS($O39:$BV39,$O$4:$BV$4,D$3) -> -6085.1064 | E39: =SUMIFS($O39:$BV39,$O$4:$BV$4,E$3) -> 0 | F39: =SUMIFS($O39:$BV39,$O$4:$BV$4,F$3) -> 0 | G39: =SUMIFS($O39:$BV39,$O$4:$BV$4,G$3) -> 0 | H39: =SUMIFS($O39:$BV39,$O$4:$BV$4,H$3) -> 0 | I39: =SUMIFS($O39:$ED39,$O$4:$ED$4,I$3) -> 0 | J39: =SUMIFS($O39:$ED39,$O$4:$ED$4,J$3) -> 0 | K39: =SUMIFS($O39:$ED39,$O$4:$ED$4,K$3) -> 0 | L39: =SUMIFS($O39:$ED39,$O$4:$ED$4,L$3) -> 0 | M39: =SUMIFS($O39:$ED39,$O$4:$ED$4,M$3) -> 0 | O39: =((1/47)*-143000)*2 -> -6085.1064
B40: Marketing | D40: =SUMIFS($O40:$BV40,$O$4:$BV$4,D$3) -> 0 | E40: =SUMIFS($O40:$BV40,$O$4:$BV$4,E$3) -> 0 | F40: =SUMIFS($O40:$BV40,$O$4:$BV$4,F$3) -> 0 | G40: =SUMIFS($O40:$BV40,$O$4:$BV$4,G$3) -> 0 | H40: =SUMIFS($O40:$BV40,$O$4:$BV$4,H$3) -> 0 | I40: =SUMIFS($O40:$ED40,$O$4:$ED$4,I$3) -> 0 | J40: =SUMIFS($O40:$ED40,$O$4:$ED$4,J$3) -> 0 | K40: =SUMIFS($O40:$ED40,$O$4:$ED$4,K$3) -> 0 | L40: =SUMIFS($O40:$ED40,$O$4:$ED$4,L$3) -> 0 | M40: =SUMIFS($O40:$ED40,$O$4:$ED$4,M$3) -> 0
B41: Investimentos | D41: =SUMIFS($O41:$BV41,$O$4:$BV$4,D$3) -> 0 | E41: =SUMIFS($O41:$BV41,$O$4:$BV$4,E$3) -> 0 | F41: =SUMIFS($O41:$BV41,$O$4:$BV$4,F$3) -> 0 | G41: =SUMIFS($O41:$BV41,$O$4:$BV$4,G$3) -> 0 | H41: =SUMIFS($O41:$BV41,$O$4:$BV$4,H$3) -> 0 | I41: =SUMIFS($O41:$ED41,$O$4:$ED$4,I$3) -> 0 | J41: =SUMIFS($O41:$ED41,$O$4:$ED$4,J$3) -> 0 | K41: =SUMIFS($O41:$ED41,$O$4:$ED$4,K$3) -> 0 | L41: =SUMIFS($O41:$ED41,$O$4:$ED$4,L$3) -> 0 | M41: =SUMIFS($O41:$ED41,$O$4:$ED$4,M$3) -> 0 | O41: =-O$7*Simulador!$E$52 -> 0 | P41: =-P$7*Simulador!$E$52 -> 0 | Q41: =-Q$7*Simulador!$E$52 -> 0 | R41: =-R$7*Simulador!$E$52 -> 0 | S41: =-S$7*Simulador!$E$52 -> 0 | T41: =-T$7*Simulador!$E$52 -> 0 | U41: =-U$7*Simulador!$E$52 -> 0 | V41: =-V$7*Simulador!$E$52 -> 0 | ... ED41: =-ED$7*Simulador!$E$52 -> 0
B42: Desenvolvimento | D42: =SUMIFS($O42:$BV42,$O$4:$BV$4,D$3) -> 0 | E42: =SUMIFS($O42:$BV42,$O$4:$BV$4,E$3) -> 0 | F42: =SUMIFS($O42:$BV42,$O$4:$BV$4,F$3) -> 0 | G42: =SUMIFS($O42:$BV42,$O$4:$BV$4,G$3) -> 0 | H42: =SUMIFS($O42:$BV42,$O$4:$BV$4,H$3) -> 0 | I42: =SUMIFS($O42:$ED42,$O$4:$ED$4,I$3) -> 0 | J42: =SUMIFS($O42:$ED42,$O$4:$ED$4,J$3) -> 0 | K42: =SUMIFS($O42:$ED42,$O$4:$ED$4,K$3) -> 0 | L42: =SUMIFS($O42:$ED42,$O$4:$ED$4,L$3) -> 0 | M42: =SUMIFS($O42:$ED42,$O$4:$ED$4,M$3) -> 0 | O42: =-Simulador!$E$58 -> 0
B43: Incentivo | D43: =SUMIFS($O43:$BV43,$O$4:$BV$4,D$3) -> 0 | E43: =SUMIFS($O43:$BV43,$O$4:$BV$4,E$3) -> 0 | F43: =SUMIFS($O43:$BV43,$O$4:$BV$4,F$3) -> 0 | G43: =SUMIFS($O43:$BV43,$O$4:$BV$4,G$3) -> 0 | H43: =SUMIFS($O43:$BV43,$O$4:$BV$4,H$3) -> 0 | I43: =SUMIFS($O43:$ED43,$O$4:$ED$4,I$3) -> 0 | J43: =SUMIFS($O43:$ED43,$O$4:$ED$4,J$3) -> 0 | K43: =SUMIFS($O43:$ED43,$O$4:$ED$4,K$3) -> 0 | L43: =SUMIFS($O43:$ED43,$O$4:$ED$4,L$3) -> 0 | M43: =SUMIFS($O43:$ED43,$O$4:$ED$4,M$3) -> 0 | O43: 0 | P43: 0 | Q43: 0 | R43: 0 | S43: 0 | T43: 0 | U43: 0 | V43: 0 | W43: 0 | X43: 0 | Y43: 0 | Z43: 0 | AA43: 0 | AB43: 0 | AC43: 0 | AD43: 0 | AE43: 0 | AF43: 0 | AG43: 0 | AH43: 0 | AI43: 0 | AJ43: 0 | AK43: 0 | AL43: 0 | AM43: 0 | AN43: 0 | AO43: 0 | AP43: 0 | AQ43: 0 | AR43: 0 | AS43: 0 | AT43: 0 | AU43: 0 | AV43: 0 | AW43: 0 | AX43: 0 | AY43: 0 | AZ43: 0 | BA43: 0 | BB43: 0 | BC43: 0 | BD43: 0 | BE43: 0 | BF43: 0 | BG43: 0 | BH43: 0 | BI43: 0 | BJ43: 0 | BK43: 0 | BL43: 0 | BM43: 0 | BN43: 0 | BO43: 0 | BP43: 0 | BQ43: 0 | BR43: 0 | BS43: 0 | BT43: 0 | BU43: 0 | BV43: 0 | BW43: 0 | BX43: 0 | BY43: 0 | BZ43: 0 | CA43: 0 | CB43: 0 | CC43: 0 | CD43: 0 | CE43: 0 | CF43: 0 | CG43: 0 | CH43: 0 | CI43: 0 | CJ43: 0 | CK43: 0 | CL43: 0 | CM43: 0 | CN43: 0 | CO43: 0 | CP43: 0 | CQ43: 0 | CR43: 0 | CS43: 0 | CT43: 0 | CU43: 0 | CV43: 0 | CW43: 0 | CX43: 0 | CY43: 0 | CZ43: 0 | DA43: 0 | DB43: 0 | DC43: 0 | DD43: 0 | DE43: 0 | DF43: 0 | DG43: 0 | DH43: 0 | DI43: 0 | DJ43: 0 | DK43: 0 | DL43: 0 | DM43: 0 | DN43: 0 | DO43: 0 | DP43: 0 | DQ43: 0 | DR43: 0 | DS43: 0 | DT43: 0 | DU43: 0 | DV43: 0 | DW43: 0 | DX43: 0 | DY43: 0 | DZ43: 0 | EA43: 0 | EB43: 0 | EC43: 0 | ED43: 0
B44: Pré-venda | D44: =SUMIFS($O44:$BV44,$O$4:$BV$4,D$3) -> 0 | E44: =SUMIFS($O44:$BV44,$O$4:$BV$4,E$3) -> 0 | F44: =SUMIFS($O44:$BV44,$O$4:$BV$4,F$3) -> 0 | G44: =SUMIFS($O44:$BV44,$O$4:$BV$4,G$3) -> 0 | H44: =SUMIFS($O44:$BV44,$O$4:$BV$4,H$3) -> 0 | I44: =SUMIFS($O44:$ED44,$O$4:$ED$4,I$3) -> 0 | J44: =SUMIFS($O44:$ED44,$O$4:$ED$4,J$3) -> 0 | K44: =SUMIFS($O44:$ED44,$O$4:$ED$4,K$3) -> 0 | L44: =SUMIFS($O44:$ED44,$O$4:$ED$4,L$3) -> 0 | M44: =SUMIFS($O44:$ED44,$O$4:$ED$4,M$3) -> 0 | O44: 0
B46: Operational Margin | D46: =SUMIFS($O46:$BV46,$O$4:$BV$4,D$3) -> 93560.269 | E46: =SUMIFS($O46:$BV46,$O$4:$BV$4,E$3) -> 130180 | F46: =SUMIFS($O46:$BV46,$O$4:$BV$4,F$3) -> 130180 | G46: =SUMIFS($O46:$BV46,$O$4:$BV$4,G$3) -> 130180 | H46: =SUMIFS($O46:$BV46,$O$4:$BV$4,H$3) -> 130180 | I46: =SUMIFS($O46:$ED46,$O$4:$ED$4,I$3) -> 0 | J46: =SUMIFS($O46:$ED46,$O$4:$ED$4,J$3) -> 0 | K46: =SUMIFS($O46:$ED46,$O$4:$ED$4,K$3) -> 0 | L46: =SUMIFS($O46:$ED46,$O$4:$ED$4,L$3) -> 0 | M46: =SUMIFS($O46:$ED46,$O$4:$ED$4,M$3) -> 0 | O46: =O29+O31+O38 -> -15868.698 | P46: =P29+P31+P38 -> 945.63333 | Q46: =Q29+Q31+Q38 -> 10848.333 | R46: =R29+R31+R38 -> 10848.333 | S46: =S29+S31+S38 -> 10848.333 | T46: =T29+T31+T38 -> 10848.333 | U46: =U29+U31+U38 -> 10848.333 | V46: =V29+V31+V38 -> 10848.333 | ... EE46: =EE29+EE31+EE38 -> 0
B47: Operational Margin Acumulada | D47: =SUMIFS($O47:$BV47,$O$3:$BV$3,D$4) -> 93560.269 | E47: =SUMIFS($O47:$BV47,$O$3:$BV$3,E$4) -> 223740.27 | F47: =SUMIFS($O47:$BV47,$O$3:$BV$3,F$4) -> 353920.27 | G47: =SUMIFS($O47:$BV47,$O$3:$BV$3,G$4) -> 484100.27 | H47: =SUMIFS($O47:$BV47,$O$3:$BV$3,H$4) -> 614280.27 | I47: =SUMIFS($O47:$ED47,$O$3:$ED$3,I$4) -> 614280.27 | J47: =SUMIFS($O47:$ED47,$O$3:$ED$3,J$4) -> 614280.27 | K47: =SUMIFS($O47:$ED47,$O$3:$ED$3,K$4) -> 614280.27 | L47: =SUMIFS($O47:$ED47,$O$3:$ED$3,L$4) -> 614280.27 | M47: =SUMIFS($O47:$ED47,$O$3:$ED$3,M$4) -> 614280.27 | O47: =O46+N47 -> -15868.698 | P47: =P46+O47 -> -14923.065 | Q47: =Q46+P47 -> -4074.7314 | R47: =R46+Q47 -> 6773.602 | S47: =S46+R47 -> 17621.935 | T47: =T46+S47 -> 28470.269 | U47: =U46+T47 -> 39318.602 | V47: =V46+U47 -> 50166.935 | ... ED47: =ED46+EC47 -> 614280.27
B49: Breakeven | D49: =MAX(O49:BV49) -> 2 | O49: =IF(AND(O46>0,P46>0),IF(N49<>0,N49,O2),0) -> 0 | P49: =IF(AND(P46>0,Q46>0),IF(O49<>0,O49,P2),0) -> 2 | Q49: =IF(AND(Q46>0,R46>0),IF(P49<>0,P49,Q2),0) -> 2 | R49: =IF(AND(R46>0,S46>0),IF(Q49<>0,Q49,R2),0) -> 2 | S49: =IF(AND(S46>0,T46>0),IF(R49<>0,R49,S2),0) -> 2 | T49: =IF(AND(T46>0,U46>0),IF(S49<>0,S49,T2),0) -> 2 | U49: =IF(AND(U46>0,V46>0),IF(T49<>0,T49,U2),0) -> 2 | V49: =IF(AND(V46>0,W46>0),IF(U49<>0,U49,V2),0) -> 2 | ... BU49: =IF(AND(BU46>0,BV46>0),IF(BT49<>0,BT49,BU2),0) -> 2 | BV49: =IF(AND(BV46>0,EE46>0),IF(BU49<>0,BU49,BV2),0) -> 0 | BW49: =IF(AND(BW46>0,EF46>0),IF(BV49<>0,BV49,BW2),0) -> 0 | BX49: =IF(AND(BX46>0,EG46>0),IF(BW49<>0,BW49,BX2),0) -> 0 | BY49: =IF(AND(BY46>0,EH46>0),IF(BX49<>0,BX49,BY2),0) -> 0 | BZ49: =IF(AND(BZ46>0,EI46>0),IF(BY49<>0,BY49,BZ2),0) -> 0 | CA49: =IF(AND(CA46>0,EJ46>0),IF(BZ49<>0,BZ49,CA2),0) -> 0 | CB49: =IF(AND(CB46>0,EK46>0),IF(CA49<>0,CA49,CB2),0) -> 0 | CC49: =IF(AND(CC46>0,EL46>0),IF(CB49<>0,CB49,CC2),0) -> 0 | ... ED49: =IF(AND(ED46>0,GM46>0),IF(EC49<>0,EC49,ED2),0) -> 0
B50: Payback | D50: =MAX(O50:BV50) -> 4 | O50: =IF(AND(O47>0,P46>0,O46>0),IF(N50<>0,N50,O2),0) -> 0 | P50: =IF(AND(P47>0,Q46>0,P46>0),IF(O50<>0,O50,P2),0) -> 0 | Q50: =IF(AND(Q47>0,R46>0,Q46>0),IF(P50<>0,P50,Q2),0) -> 0 | R50: =IF(AND(R47>0,S46>0,R46>0),IF(Q50<>0,Q50,R2),0) -> 4 | S50: =IF(AND(S47>0,T46>0,S46>0),IF(R50<>0,R50,S2),0) -> 4 | T50: =IF(AND(T47>0,U46>0,T46>0),IF(S50<>0,S50,T2),0) -> 4 | U50: =IF(AND(U47>0,V46>0,U46>0),IF(T50<>0,T50,U2),0) -> 4 | V50: =IF(AND(V47>0,W46>0,V46>0),IF(U50<>0,U50,V2),0) -> 4 | ... BU50: =IF(AND(BU47>0,BV46>0,BU46>0),IF(BT50<>0,BT50,BU2),0) -> 4 | BV50: =IF(AND(BV47>0,EE46>0,BV46>0),IF(BU50<>0,BU50,BV2),0) -> 0 | BW50: =IF(AND(BW47>0,EF46>0,BW46>0),IF(BV50<>0,BV50,BW2),0) -> 0 | BX50: =IF(AND(BX47>0,EG46>0,BX46>0),IF(BW50<>0,BW50,BX2),0) -> 0 | BY50: =IF(AND(BY47>0,EH46>0,BY46>0),IF(BX50<>0,BX50,BY2),0) -> 0 | BZ50: =IF(AND(BZ47>0,EI46>0,BZ46>0),IF(BY50<>0,BY50,BZ2),0) -> 0 | CA50: =IF(AND(CA47>0,EJ46>0,CA46>0),IF(BZ50<>0,BZ50,CA2),0) -> 0 | CB50: =IF(AND(CB47>0,EK46>0,CB46>0),IF(CA50<>0,CA50,CB2),0) -> 0 | CC50: =IF(AND(CC47>0,EL46>0,CC46>0),IF(CB50<>0,CB50,CC2),0) -> 0 | ... ED50: =IF(AND(ED47>0,GM46>0,ED46>0),IF(EC50<>0,EC50,ED2),0) -> 0

Sheet Cenário 2
P1: 1 | Q1: =P1+1 -> 2 | R1: =Q1+1 -> 3 | S1: =R1+1 -> 4 | T1: =S1+1 -> 5 | U1: =T1+1 -> 6 | V1: =U1+1 -> 7 | W1: =V1+1 -> 8 | X1: =W1+1 -> 9 | ... ED1: =EC1+1 -> 119
O2: 1 | P2: =O2+1 -> 2 | Q2: =P2+1 -> 3 | R2: =Q2+1 -> 4 | S2: =R2+1 -> 5 | T2: =S2+1 -> 6 | U2: =T2+1 -> 7 | V2: =U2+1 -> 8 | W2: =V2+1 -> 9 | ... ED2: =EC2+1 -> 120
D3: Ano 1 | E3: Ano 2 | F3: Ano 3 | G3: Ano 4 | H3: Ano 5 | I3: Ano 6 | J3: Ano 7 | K3: Ano 8 | L3: Ano 9 | M3: Ano 10 | O3: Mês 1 | P3: Mês 2 | Q3: Mês 3 | R3: Mês 4 | S3: Mês 5 | T3: Mês 6 | U3: Mês 7 | V3: Mês 8 | W3: Mês 9 | X3: Mês 10 | Y3: Mês 11 | Z3: Mês 12 | AA3: Mês 13 | AB3: Mês 14 | AC3: Mês 15 | AD3: Mês 16 | AE3: Mês 17 | AF3: Mês 18 | AG3: Mês 19 | AH3: Mês 20 | AI3: Mês 21 | AJ3: Mês 22 | AK3: Mês 23 | AL3: Mês 24 | AM3: Mês 25 | AN3: Mês 26 | AO3: Mês 27 | AP3: Mês 28 | AQ3: Mês 29 | AR3: Mês 30 | AS3: Mês 31 | AT3: Mês 32 | AU3: Mês 33 | AV3: Mês 34 | AW3: Mês 35 | AX3: Mês 36 | AY3: Mês 37 | AZ3: Mês 38 | BA3: Mês 39 | BB3: Mês 40 | BC3: Mês 41 | BD3: Mês 42 | BE3: Mês 43 | BF3: Mês 44 | BG3: Mês 45 | BH3: Mês 46 | BI3: Mês 47 | BJ3: Mês 48 | BK3: Mês 49 | BL3: Mês 50 | BM3: Mês 51 | BN3: Mês 52 | BO3: Mês 53 | BP3: Mês 54 | BQ3: Mês 55 | BR3: Mês 56 | BS3: Mês 57 | BT3: Mês 58 | BU3: Mês 59 | BV3: Mês 60 | BW3: Mês 61 | BX3: Mês 62 | BY3: Mês 63 | BZ3: Mês 64 | CA3: Mês 65 | CB3: Mês 66 | CC3: Mês 67 | CD3: Mês 68 | CE3: Mês 69 | CF3: Mês 70 | CG3: Mês 71 | CH3: Mês 72 | CI3: Mês 73 | CJ3: Mês 74 | CK3: Mês 75 | CL3: Mês 76 | CM3: Mês 77 | CN3: Mês 78 | CO3: Mês 79 | CP3: Mês 80 | CQ3: Mês 81 | CR3: Mês 82 | CS3: Mês 83 | CT3: Mês 84 | CU3: Mês 85 | CV3: Mês 86 | CW3: Mês 87 | CX3: Mês 88 | CY3: Mês 89 | CZ3: Mês 90 | DA3: Mês 91 | DB3: Mês 92 | DC3: Mês 93 | DD3: Mês 94 | DE3: Mês 95 | DF3: Mês 96 | DG3: Mês 97 | DH3: Mês 98 | DI3: Mês 99 | DJ3: Mês 100 | DK3: Mês 101 | DL3: Mês 102 | DM3: Mês 103 | DN3: Mês 104 | DO3: Mês 105 | DP3: Mês 106 | DQ3: Mês 107 | DR3: Mês 108 | DS3: Mês 109 | DT3: Mês 110 | DU3: Mês 111 | DV3: Mês 112 | DW3: Mês 113 | DX3: Mês 114 | DY3: Mês 115 | DZ3: Mês 116 | EA3: Mês 117 | EB3: Mês 118 | EC3: Mês 119 | ED3: Mês 120
D4: Mês 12 | E4: Mês 24 | F4: Mês 36 | G4: Mês 48 | H4: Mês 60 | I4: Mês 72 | J4: Mês 84 | K4: Mês 96 | L4: Mês 108 | M4: Mês 120 | O4: Ano 1 | P4: Ano 1 | Q4: Ano 1 | R4: Ano 1 | S4: Ano 1 | T4: Ano 1 | U4: Ano 1 | V4: Ano 1 | W4: Ano 1 | X4: Ano 1 | Y4: Ano 1 | Z4: Ano 1 | AA4: Ano 2 | AB4: Ano 2 | AC4: Ano 2 | AD4: Ano 2 | AE4: Ano 2 | AF4: Ano 2 | AG4: Ano 2 | AH4: Ano 2 | AI4: Ano 2 | AJ4: Ano 2 | AK4: Ano 2 | AL4: Ano 2 | AM4: Ano 3 | AN4: Ano 3 | AO4: Ano 3 | AP4: Ano 3 | AQ4: Ano 3 | AR4: Ano 3 | AS4: Ano 3 | AT4: Ano 3 | AU4: Ano 3 | AV4: Ano 3 | AW4: Ano 3 | AX4: Ano 3 | AY4: Ano 4 | AZ4: Ano 4 | BA4: Ano 4 | BB4: Ano 4 | BC4: Ano 4 | BD4: Ano 4 | BE4: Ano 4 | BF4: Ano 4 | BG4: Ano 4 | BH4: Ano 4 | BI4: Ano 4 | BJ4: Ano 4 | BK4: Ano 5 | BL4: Ano 5 | BM4: Ano 5 | BN4: Ano 5 | BO4: Ano 5 | BP4: Ano 5 | BQ4: Ano 5 | BR4: Ano 5 | BS4: Ano 5 | BT4: Ano 5 | BU4: Ano 5 | BV4: Ano 5 | BW4: Ano 6 | BX4: Ano 6 | BY4: Ano 6 | BZ4: Ano 6 | CA4: Ano 6 | CB4: Ano 6 | CC4: Ano 6 | CD4: Ano 6 | CE4: Ano 6 | CF4: Ano 6 | CG4: Ano 6 | CH4: Ano 6 | CI4: Ano 7 | CJ4: Ano 7 | CK4: Ano 7 | CL4: Ano 7 | CM4: Ano 7 | CN4: Ano 7 | CO4: Ano 7 | CP4: Ano 7 | CQ4: Ano 7 | CR4: Ano 7 | CS4: Ano 7 | CT4: Ano 7 | CU4: Ano 8 | CV4: Ano 8 | CW4: Ano 8 | CX4: Ano 8 | CY4: Ano 8 | CZ4: Ano 8 | DA4: Ano 8 | DB4: Ano 8 | DC4: Ano 8 | DD4: Ano 8 | DE4: Ano 8 | DF4: Ano 8 | DG4: Ano 9 | DH4: Ano 9 | DI4: Ano 9 | DJ4: Ano 9 | DK4: Ano 9 | DL4: Ano 9 | DM4: Ano 9 | DN4: Ano 9 | DO4: Ano 9 | DP4: Ano 9 | DQ4: Ano 9 | DR4: Ano 9 | DS4: Ano 10 | DT4: Ano 10 | DU4: Ano 10 | DV4: Ano 10 | DW4: Ano 10 | DX4: Ano 10 | DY4: Ano 10 | DZ4: Ano 10 | EA4: Ano 10 | EB4: Ano 10 | EC4: Ano 10 | ED4: Ano 10
